Workbook

Sheet BASE
A1: Ciclo | B1: Cd Gerencia | C1: Nombre Gerencia | D1: Cd Setor | E1: Nombre Setor | F1: Código de consultora | G1: Nombre de consultora | H1: Color | I1: Código de grupo | J1: Objetivo Facturación | K1: Real Facturación | L1: Cumplimiento Facturación | M1: Objetivo Activas | N1: Real Activas | O1: Cumplimiento Activas | P1: Real Activas plata o mas | Q1: Real Activas Bronce o Plata | R1: Saldo | S1: Disponibles | T1: Inactiva 1 | U1: Inactiva 2 | V1: Inactiva 3 | W1: Inactiva 4 | X1: Inactiva 5 | Y1: Inactiva 6 | Z1: Recuperos | AA1: %Actividad | AB1: Activas Frecuentes | AC1: %Actividad Frecuente | AD1: Inicios | AE1: Reinicios | AF1: Productividad | AG1: Ganancia estimada
A2: 202611 | B2: 700000003 | C2: GERENCIA VENTAS ARTE KARENTH | D2: 700000459 | E2: SECTOR MATICES CLERY | F2: 1021104 | G2: CARMENZA RONCANCIO GACHANCIPA | H2: ORO | I2: 7841 | J2: 48994379 | K2: 49623875 | L2: 1.0128 | M2: 145 | N2: 146 | O2: 1.0069 | P2: 0 | Q2: 0 | R2: 10 | S2: 242 | T2: 57 | U2: 27 | V2: 12 | W2: 7 | X2: 4 | Y2: 3 | Z2: 13 | AA2: 0.6033 | AB2: 124 | AC2: 0.5124 | AD2: 7 | AE2: 3 | AF2: 10.643836 | AG2: 3225551.9
A3: 202611 | B3: 700000003 | C3: GERENCIA VENTAS ARTE KARENTH | D3: 700000459 | E3: SECTOR MATICES CLERY | F3: 813431 | G3: Luz Dary Chacon Gaitan | H3: ORO | I3: 8425 | J3: 64916190 | K3: 69917557 | L3: 1.077 | M3: 149 | N3: 153 | O3: 1.0268 | P3: 0 | Q3: 0 | R3: 4 | S3: 246 | T3: 48 | U3: 25 | V3: 20 | W3: 7 | X3: 8 | Y3: 2 | Z3: 11 | AA3: 0.622 | AB3: 136 | AC3: 0.5528 | AD3: 4 | AE3: 2 | AF3: 11.45098 | AG3: 4037738.9
A4: 202611 | B4: 700000003 | C4: GERENCIA VENTAS ARTE KARENTH | D4: 700000459 | E4: SECTOR MATICES CLERY | F4: 768496 | G4: LUZ ADRIANA PAEZ VIGOYA | I4: 8481 | J4: 56758471 | K4: 62664913 | L4: 1.1041 | M4: 141 | N4: 143 | O4: 1.0142 | P4: 0 | Q4: 0 | R4: 2 | S4: 219 | T4: 49 | U4: 15 | V4: 12 | W4: 9 | X4: 12 | Y4: 3 | Z4: 13 | AA4: 0.653 | AB4: 126 | AC4: 0.5753 | AD4: 4 | AE4: 0 | AF4: 11.951049 | AG4: 3603232.5
A5: 202611 | B5: 700000003 | C5: GERENCIA VENTAS ARTE KARENTH | D5: 700000459 | E5: SECTOR MATICES CLERY | F5: 1077740 | G5: LUZ MARY LUNA LEON | H5: ORO | I5: 9291 | J5: 26606005 | K5: 25333760 | L5: 0.9522 | M5: 88 | N5: 83 | O5: 0.9432 | P5: 0 | Q5: 0 | R5: 0 | S5: 141 | T5: 37 | U5: 16 | V5: 5 | W5: 9 | X5: 5 | Y5: 3 | Z5: 6 | AA5: 0.5887 | AB5: 68 | AC5: 0.4823 | AD5: 6 | AE5: 3 | AF5: 8.686747 | AG5: 344539.14
A6: 202611 | B6: 700000003 | C6: GERENCIA VENTAS ARTE KARENTH | D6: 700000459 | E6: SECTOR MATICES CLERY | F6: 1099653 | G6: ANGELA MIREYA MONTENEGRO ROMERO | I6: 9334 | J6: 36505654 | K6: 39088220 | L6: 1.0707 | M6: 98 | N6: 102 | O6: 1.0408 | P6: 0 | Q6: 0 | R6: 3 | S6: 155 | T6: 30 | U6: 12 | V6: 11 | W6: 6 | X6: 5 | Y6: 6 | Z6: 7 | AA6: 0.6581 | AB6: 91 | AC6: 0.5871 | AD6: 2 | AE6: 2 | AF6: 12.117647 | AG6: 2154738.1
A7: 202611 | B7: 700000003 | C7: GERENCIA VENTAS ARTE KARENTH | D7: 700000459 | E7: SECTOR MATICES CLERY | F7: 985990 | G7: MARIA CRISTINA RUBIO | H7: ORO | I7: 9400 | J7: 17013949 | K7: 15862661 | L7: 0.9323 | M7: 57 | N7: 55 | O7: 0.9649 | P7: 0 | Q7: 0 | R7: 1 | S7: 94 | T7: 15 | U7: 11 | V7: 13 | W7: 8 | X7: 9 | Y7: 4 | Z7: 0 | AA7: 0.5851 | AB7: 47 | AC7: 0.5 | AD7: 8 | AE7: 0 | AF7: 8.2 | AG7: 241112.45
A9: ANTERIOR
A10: Ciclo | B10: Cd Gerencia | C10: Nombre Gerencia | D10: Cd Setor | E10: Nombre Setor | F10: Código de consultora | G10: Nombre de consultora | H10: Color | I10: Código de grupo | J10: Objetivo Facturación | K10: Real Facturación | L10: Cumplimiento Facturación | M10: Objetivo Activas | N10: Real Activas | O10: Cumplimiento Activas | P10: Real Activas plata o mas | Q10: Real Activas Bronce o Plata | R10: Saldo | S10: Disponibles | T10: Inactiva 1 | U10: Inactiva 2 | V10: Inactiva 3 | W10: Inactiva 4 | X10: Inactiva 5 | Y10: Inactiva 6 | Z10: Recuperos | AA10: %Actividad | AB10: Activas Frecuentes | AC10: %Actividad Frecuente | AD10: Inicios | AE10: Reinicios | AF10: Productividad | AG10: Ganancia estimada | AH10: Real Activas plata o mas | AI10: Real Activas Bronce o Plata | AJ10: Saldo | AK10: Disponibles | AL10: Inactiva 1 | AM10: Inactiva 2 | AN10: Inactiva 3 | AO10: Inactiva 4 | AP10: Inactiva 5 | AQ10: Inactiva 6 | AR10: Recuperos | AS10: %Actividad | AT10: Activas Frecuentes | AU10: %Actividad Frecuente | AV10: Inicios | AW10: Reinicios | AX10: Productividad | AY10: Ganancia estimada
A11: 202611 | B11: 700000003 | C11: GERENCIA VENTAS ARTE KARENTH | D11: 700000459 | E11: SECTOR MATICES CLERY | F11: 1021104 | G11: CARMENZA RONCANCIO GACHANCIPA | H11: ORO | I11: 7841 | J11: 48994379 | K11: 47628458 | L11: 0.9721 | M11: 145 | N11: 137 | O11: 0.9448 | P11: 0 | Q11: 0 | R11: 10 | S11: 242 | T11: 65 | U11: 27 | V11: 13 | W11: 7 | X11: 4 | Y11: 3 | Z11: 13 | AA11: 0.5661 | AB11: 115 | AC11: 0.4752 | AD11: 7 | AE11: 3 | AF11: 10.883212 | AG11: 990671.93 | AH11: 0 | AI11: 0 | AJ11: -18 | AK11: 222 | AL11: 160 | AM11: 37 | AN11: 13 | AO11: 19 | AP11: 4 | AQ11: 3 | AR11: 1 | AS11: 0.0541 | AT11: 10 | AU11: 0.045 | AV11: 0 | AW11: 1 | AX11: 9583333333 | AY11: 0
A12: 202611 | B12: 700000003 | C12: GERENCIA VENTAS ARTE KARENTH | D12: 700000459 | E12: SECTOR MATICES CLERY | F12: 813431 | G12: Luz Dary Chacon Gaitan | H12: ORO | I12: 8425 | J12: 64916190 | K12: 67298901 | L12: 1.0367 | M12: 149 | N12: 144 | O12: 0.9664 | P12: 0 | Q12: 0 | R12: 3 | S12: 245 | T12: 55 | U12: 26 | V12: 20 | W12: 7 | X12: 9 | Y12: 2 | Z12: 10 | AA12: 0.5878 | AB12: 128 | AC12: 0.5224 | AD12: 4 | AE12: 2 | AF12: 11.722222 | AG12: 2826553.8 | AH12: 0 | AI12: 0 | AJ12: -7 | AK12: 30 | AL12: 19 | AM12: 3 | AN12: 4 | AO12: 7 | AP12: 3 | AQ12: 0 | AR12: 0 | AS12: 0.1333 | AT12: 4 | AU12: 0.1333 | AV12: 0 | AW12: 0 | AX12: 11.75 | AY12: 0
A13: 202611 | B13: 700000003 | C13: GERENCIA VENTAS ARTE KARENTH | D13: 700000459 | E13: SECTOR MATICES CLERY | F13: 768496 | G13: LUZ ADRIANA PAEZ VIGOYA | I13: 8481 | J13: 56758471 | K13: 60770245 | L13: 1.0707 | M13: 141 | N13: 135 | O13: 0.9574 | P13: 0 | Q13: 0 | R13: 0 | S13: 217 | T13: 55 | U13: 15 | V13: 12 | W13: 11 | X13: 12 | Y13: 3 | Z13: 11 | AA13: 0.6221 | AB13: 120 | AC13: 0.553 | AD13: 4 | AE13: 0 | AF13: 12.22963 | AG13: 2066188.3 | AH13: 0 | AI13: 0 | AJ13: -1 | AK13: 135 | AL13: 91 | AM13: 10 | AN13: 22 | AO13: 5 | AP13: 5 | AQ13: 11 | AR13: 0 | AS13: 0.0889 | AT13: 7 | AU13: 0.0519 | AV13: 4 | AW13: 1 | AX13: 9666666667 | AY13: 0
A14: 202611 | B14: 700000003 | C14: GERENCIA VENTAS ARTE KARENTH | D14: 700000459 | E14: SECTOR MATICES CLERY | F14: 1077740 | G14: LUZ MARY LUNA LEON | H14: ORO | I14: 9291 | J14: 26606005 | K14: 24213046 | L14: 0.9101 | M14: 88 | N14: 79 | O14: 0.8977 | P14: 0 | Q14: 0 | R14: 0 | S14: 141 | T14: 40 | U14: 17 | V14: 5 | W14: 9 | X14: 5 | Y14: 3 | Z14: 6 | AA14: 0.5603 | AB14: 64 | AC14: 0.4539 | AD14: 6 | AE14: 3 | AF14: 8.7721519 | AG14: 308716.34 | AH14: 0 | AI14: 0 | AJ14: 0 | AK14: 1 | AL14: 1 | AM14: 0 | AN14: 0 | AO14: 0 | AP14: 0 | AQ14: 0 | AR14: 0 | AS14: 0 | AT14: 0 | AU14: 0 | AV14: 0 | AW14: 0 | AX14: 0 | AY14: 0
A15: 202611 | B15: 700000003 | C15: GERENCIA VENTAS ARTE KARENTH | D15: 700000459 | E15: SECTOR MATICES CLERY | F15: 1099653 | G15: ANGELA MIREYA MONTENEGRO ROMERO | I15: 9334 | J15: 36505654 | K15: 38474336 | L15: 1.0539 | M15: 98 | N15: 101 | O15: 1.0306 | P15: 0 | Q15: 0 | R15: 3 | S15: 155 | T15: 31 | U15: 12 | V15: 11 | W15: 6 | X15: 5 | Y15: 6 | Z15: 7 | AA15: 0.6516 | AB15: 90 | AC15: 0.5806 | AD15: 2 | AE15: 2 | AF15: 12.158416 | AG15: 2120897.8 | AH15: 0 | AI15: 0 | AJ15: 0 | AK15: 20 | AL15: 15 | AM15: 2 | AN15: 3 | AO15: 0 | AP15: 0 | AQ15: 1 | AR15: 0 | AS15: 0 | AT15: 0 | AU15: 0 | AV15: 0 | AW15: 0 | AX15: 0 | AY15: 0
A16: 202611 | B16: 700000003 | C16: GERENCIA VENTAS ARTE KARENTH | D16: 700000459 | E16: SECTOR MATICES CLERY | F16: 985990 | G16: MARIA CRISTINA RUBIO | H16: ORO | I16: 9400 | J16: 17013949 | K16: 14828454 | L16: 0.8715 | M16: 57 | N16: 52 | O16: 0.9123 | P16: 0 | Q16: 0 | R16: 1 | S16: 94 | T16: 18 | U16: 11 | V16: 13 | W16: 8 | X16: 9 | Y16: 4 | Z16: 0 | AA16: 0.5532 | AB16: 44 | AC16: 0.4681 | AD16: 8 | AE16: 0 | AF16: 7.9423077 | AG16: 211305.47 | AH16: 0 | AI16: 0 | AJ16: -20 | AK16: 210 | AL16: 141 | AM16: 35 | AN16: 23 | AO16: 20 | AP16: 6 | AQ16: 9 | AR16: 3 | AS16: 0.0524 | AT16: 8 | AU16: 0.0381 | AV16: 0 | AW16: 0 | AX16: 1063636364 | AY16: 0

Sheet ASI VAMOS
C2: FACTURACIÓN
C3: SECTOR ORIGEN | D3: LIDER DE NEGOCIOS | E3: DESAFIO FACTURACION | F3: FACTURACION A HOY | H3: CUMPLIMIENTO DE FACTURACION | I3: AVANCE % | J3: PRODUCTIVIDAD | K3: FALTA PARA EL 100% | L3: Cuanto falta para el 110% | M3: Pedidos
C4: =BASE!E2 -> SECTOR MATICES CLERY | D4: =BASE!G2 -> CARMENZA RONCANCIO GACHANCIPA | E4: =BASE!J2 -> 48994379 | F4: =BASE!K2 -> 49623875 | H4: =F4/E4 -> 1.0128483 | I4: =BASE!L2-BASE!L11 -> 0.0407 | J4: =F4/F13 -> 339889.55 | K4: =E4-F4 -> -629496.07 | L4: =E4*110%-(F4) -> 4269941.8 | M4: =L4/200000 -> 21.349709
C5: =BASE!E3 -> SECTOR MATICES CLERY | D5: =BASE!G3 -> Luz Dary Chacon Gaitan | E5: =BASE!J3 -> 64916190 | F5: =BASE!K3 -> 69917557 | H5: =F5/E5 -> 1.0770434 | I5: =BASE!L3-BASE!L12 -> 0.0403 | J5: =F5/F14 -> 456977.5 | K5: =E5-F5 -> -5001367.1 | L5: =E5*110%-(F5) -> 1490251.9 | M5: =L5/200000 -> 7.4512595
C6: =BASE!E4 -> SECTOR MATICES CLERY | D6: =BASE!G4 -> LUZ ADRIANA PAEZ VIGOYA | E6: =BASE!J4 -> 56758471 | F6: =BASE!K4 -> 62664913 | H6: =F6/E6 -> 1.1040627 | I6: =BASE!L4-BASE!L13 -> 0.0334 | J6: =F6/F15 -> 438216.17 | K6: =E6-F6 -> -5906442.5 | L6: =E6*110%-(F6) -> -230595.43 | M6: =L6/200000 -> -1.1529771
C7: =BASE!E5 -> SECTOR MATICES CLERY | D7: =BASE!G5 -> LUZ MARY LUNA LEON | E7: =BASE!J5 -> 26606005 | F7: =BASE!K5 -> 25333760 | H7: =F7/E7 -> 0.95218202 | I7: =BASE!L5-BASE!L14 -> 0.0421 | J7: =F7/F16 -> 305226.02 | K7: =E7-F7 -> 1272245.4 | L7: =E7*110%-(F7) -> 3932846 | M7: =L7/200000 -> 19.66423
C8: =BASE!E6 -> SECTOR MATICES CLERY | D8: =BASE!G6 -> ANGELA MIREYA MONTENEGRO ROMERO | E8: =BASE!J6 -> 36505654 | F8: =BASE!K6 -> 39088220 | H8: =F8/E8 -> 1.0707443 | I8: =BASE!L6-BASE!L15 -> 0.0168 | J8: =F8/F17 -> 383217.84 | K8: =E8-F8 -> -2582565.6 | L8: =E8*110%-(F8) -> 1067999.8 | M8: =L8/200000 -> 5.3399992
C9: =BASE!#REF! -> #REF! | D9: =BASE!G7 -> MARIA CRISTINA RUBIO | E9: =BASE!J7 -> 17013949 | F9: =BASE!K7 -> 15862661 | H9: =F9/E9 -> 0.9323327 | I9: =BASE!L7-BASE!L16 -> 0.0608 | J9: =F9/F18 -> 288412.02 | K9: =E9-F9 -> 1151287.9 | L9: =E9*110%-(F9) -> 2852682.8 | M9: =L9/200000 -> 14.263414
B10: Activa C5
C11: ACTIVAS | F11: ACTIVAS
B12: CUMPLIMIENTO DE FACTURACION | C12: SECTOR ORIGEN | D12: GRUPO LIDER | E12: DESAFIO ACTIVAS | F12: ACTIVAS A HOY | H12: ACTIVAS QUE FALTAN 100% | I12: % CUMPLIMIENTO ACTIVAS | J12: AVANCE ACTIVAS | K12: FALTA PARA EL 105%
B13: =A13/#REF! -> #REF! | C13: =C4 -> SECTOR MATICES CLERY | D13: =D4 -> CARMENZA RONCANCIO GACHANCIPA | E13: =BASE!M2 -> 145 | F13: =BASE!N2 -> 146 | H13: =(-1*(F13-E13)) -> -1 | I13: =F13/E13 -> 1.0068966 | J13: =BASE!N2-BASE!N11 -> 9 | K13: =E13*105%-(F13) -> 6.25
B14: =A14/#REF! -> #REF! | C14: =C5 -> SECTOR MATICES CLERY | D14: =D5 -> Luz Dary Chacon Gaitan | E14: =BASE!M3 -> 149 | F14: =BASE!N3 -> 153 | H14: =(-1*(F14-E14)) -> -4 | I14: =F14/E14 -> 1.0268456 | J14: =BASE!N3-BASE!N12 -> 9 | K14: =E14*105%-(F14) -> 3.45
B15: =A15/#REF! -> #REF! | C15: =C6 -> SECTOR MATICES CLERY | D15: =D6 -> LUZ ADRIANA PAEZ VIGOYA | E15: =BASE!M4 -> 141 | F15: =BASE!N4 -> 143 | H15: =(-1*(F15-E15)) -> -2 | I15: =F15/E15 -> 1.0141844 | J15: =BASE!N4-BASE!N13 -> 8 | K15: =E15*105%-(F15) -> 5.05
B16: =A16/#REF! -> #REF! | C16: =C7 -> SECTOR MATICES CLERY | D16: =D7 -> LUZ MARY LUNA LEON | E16: =BASE!M5 -> 88 | F16: =BASE!N5 -> 83 | H16: =(-1*(F16-E16)) -> 5 | I16: =F16/E16 -> 0.94318182 | J16: =BASE!N5-BASE!N14 -> 4 | K16: =E16*105%-(F16) -> 9.4
B17: =A17/#REF! -> #REF! | C17: =C8 -> SECTOR MATICES CLERY | D17: =D8 -> ANGELA MIREYA MONTENEGRO ROMERO | E17: =BASE!M6 -> 98 | F17: =BASE!N6 -> 102 | H17: =(-1*(F17-E17)) -> -4 | I17: =F17/E17 -> 1.0408163 | J17: =BASE!N6-BASE!N15 -> 1 | K17: =E17*105%-(F17) -> 0.9
C18: =C9 -> #REF! | D18: =D9 -> MARIA CRISTINA RUBIO | E18: =BASE!M7 -> 57 | F18: =BASE!N7 -> 55 | H18: =(-1*(F18-E18)) -> 2 | I18: =F18/E18 -> 0.96491228 | J18: =BASE!N7-BASE!N16 -> 3 | K18: =E18*105%-(F18) -> 4.85
C21: SALDO
C22: SECTOR ORIGEN | D22: GRUPO LIDER | E22: SALDO | F22: FALTA SALDO PROYECTADO +2 | G22: RECUPEROS Esta Mañana | H22: RECUPEROS | I22: INICIOS | J22: REINICIOS | K22: AVANCE | L22: Total Inicios y Reinicios | M22: Desafio inicios+reinicios Escala de excelencia | N22: Cuantos faltan | O22: Desafio de Recuperos | P22: Cuantos faltan | Q22: compromiso | R22: Faltan
C23: =C13 -> SECTOR MATICES CLERY | D23: =D13 -> CARMENZA RONCANCIO GACHANCIPA | E23: =BASE!R2 -> 10 | F23: =E23-2 -> 8 | G23: 11 | H23: =BASE!Z2 -> 13 | I23: =BASE!AD2 -> 7 | J23: =BASE!AE2 -> 3 | K23: =BASE!R2-BASE!R11 -> 0 | L23: =SUM(I23+J23) -> 10 | M23: 14 | N23: =M23-L23 -> 4 | O23: 8 | P23: =O23-H23 -> -5 | Q23: 1 | R23: =Q23-K23 -> 1
C24: =C14 -> SECTOR MATICES CLERY | D24: =D14 -> Luz Dary Chacon Gaitan | E24: =BASE!R3 -> 4 | F24: =E24-2 -> 2 | G24: 8 | H24: =BASE!Z3 -> 11 | I24: =BASE!AD3 -> 4 | J24: =BASE!AE3 -> 2 | K24: =BASE!R3-BASE!R12 -> 1 | L24: =SUM(I24+J24) -> 6 | M24: 15 | N24: =M24-L24 -> 9 | O24: 7 | P24: =O24-H24 -> -4 | Q24: 3 | R24: =Q24-K24 -> 2
C25: =C15 -> SECTOR MATICES CLERY | D25: =D15 -> LUZ ADRIANA PAEZ VIGOYA | E25: =BASE!R4 -> 2 | F25: =E25-2 -> 0 | G25: 10 | H25: =BASE!Z4 -> 13 | I25: =BASE!AD4 -> 4 | J25: =BASE!AE4 -> 0 | K25: =BASE!R4-BASE!R13 -> 2 | L25: =SUM(I25+J25) -> 4 | M25: 16 | N25: =M25-L25 -> 12 | O25: 9 | P25: =O25-H25 -> -4 | Q25: 2 | R25: =Q25-K25 -> 0
C26: =C16 -> SECTOR MATICES CLERY | D26: =D16 -> LUZ MARY LUNA LEON | E26: =BASE!R5 -> 0 | F26: =E26-2 -> -2 | G26: 4 | H26: =BASE!Z5 -> 6 | I26: =BASE!AD5 -> 6 | J26: =BASE!AE5 -> 3 | K26: =BASE!R5-BASE!R14 -> 0 | L26: =SUM(I26+J26) -> 9 | M26: 4 | N26: =M26-L26 -> -5 | O26: 5 | P26: =O26-H26 -> -1 | Q26: 7 | R26: =Q26-K26 -> 7
C27: =C17 -> SECTOR MATICES CLERY | D27: =D17 -> ANGELA MIREYA MONTENEGRO ROMERO | E27: =BASE!R6 -> 3 | F27: =E27-2 -> 1 | G27: 6 | H27: =BASE!Z6 -> 7 | I27: =BASE!AD6 -> 2 | J27: =BASE!AE6 -> 2 | K27: =BASE!R6-BASE!R15 -> 0 | L27: =SUM(I27+J27) -> 4 | M27: 6 | N27: =M27-L27 -> 2 | O27: 6 | P27: =O27-H27 -> -1 | Q27: 1 | R27: =Q27-K27 -> 1
C28: =C18 -> #REF! | D28: =D18 -> MARIA CRISTINA RUBIO | E28: =BASE!R7 -> 1 | F28: =E28-2 -> -1 | G28: 0 | H28: =BASE!Z7 -> 0 | I28: =BASE!AD7 -> 8 | J28: =BASE!AE7 -> 0 | K28: =BASE!R7-BASE!R16 -> 0 | L28: =SUM(I28+J28) -> 8 | M28: 5 | N28: =M28-L28 -> -3 | O28: 5 | P28: =O28-H28 -> 5 | Q28: 3 | R28: =Q28-K28 -> 3
C30: DISPONIBLES
C31: SECTOR ORIGEN | D31: GRUPO LIDER | E31: DISPONIBLES INICIALES | F31: DISPONIBLES A HOY | H31: DISPONIBLES PROYECTADAS | I31: FALTAN | J31: AVANCE
A32: 7 | B32: 202 | C32: =C4 -> SECTOR MATICES CLERY | D32: =D23 -> CARMENZA RONCANCIO GACHANCIPA | E32: 222 | F32: 242 | H32: 240 | I32: =H32-F32 -> -2 | J32: =BASE!S2-BASE!S11 -> 0
B33: 182 | C33: =C5 -> SECTOR MATICES CLERY | D33: =D24 -> Luz Dary Chacon Gaitan | E33: 229 | F33: 245 | H33: 244 | I33: =H33-F33 -> -1 | J33: =BASE!S3-BASE!S12 -> 1
B34: 136 | C34: =C6 -> SECTOR MATICES CLERY | D34: =D25 -> LUZ ADRIANA PAEZ VIGOYA | E34: 202 | F34: 219 | H34: 232 | I34: =H34-F34 -> 13 | J34: =BASE!S4-BASE!S13 -> 2
B35: 224 | C35: =C7 -> SECTOR MATICES CLERY | D35: =D26 -> LUZ MARY LUNA LEON | E35: 127 | F35: 141 | H35: 146 | I35: =H35-F35 -> 5 | J35: =BASE!S5-BASE!S14 -> 0
B36: 189 | C36: =C8 -> SECTOR MATICES CLERY | D36: =D27 -> ANGELA MIREYA MONTENEGRO ROMERO | E36: 145 | F36: 155 | H36: 160 | I36: =H36-F36 -> 5 | J36: =BASE!S6-BASE!S15 -> 0
B37: 143 | C37: =C9 -> #REF! | D37: =D28 -> MARIA CRISTINA RUBIO | E37: 86 | F37: 94 | H37: 82 | I37: =H37-F37 -> -12 | J37: =BASE!S7-BASE!S16 -> 0
C40: RETENCIÓN I2
C41: SECTOR ORIGEN | D41: GRUPO LIDER | E41: META RETENCIÓN I2 | F41: FALTA I2 ACTIVARSE | H41: % RETENCIÓN META 8% | I41: AVANCE RETENCION I2
C42: =C4 -> SECTOR MATICES CLERY | D42: =D32 -> CARMENZA RONCANCIO GACHANCIPA | E42: =E32*8% -> 17.76 | F42: =F69-E42 -> 9.24 | H42: =F69/F32 -> 0.11157025 | I42: =BASE!U11-BASE!U2 -> 0
C43: =C5 -> SECTOR MATICES CLERY | D43: =D33 -> Luz Dary Chacon Gaitan | E43: =E33*8% -> 18.32 | F43: =F70-E43 -> 6.68 | H43: =F70/F33 -> 0.10204082 | I43: =BASE!U12-BASE!U3 -> 1
C44: =C6 -> SECTOR MATICES CLERY | D44: =D34 -> LUZ ADRIANA PAEZ VIGOYA | E44: =E34*8% -> 16.16 | F44: =F71-E44 -> -1.16 | H44: =F71/F34 -> 0.068493151 | I44: =BASE!U13-BASE!U4 -> 0
C45: =C7 -> SECTOR MATICES CLERY | D45: =D35 -> LUZ MARY LUNA LEON | E45: =E35*8% -> 10.16 | F45: =F72-E45 -> 5.84 | H45: =F72/F35 -> 0.11347518 | I45: =BASE!U14-BASE!U5 -> 1
C46: =C8 -> SECTOR MATICES CLERY | D46: =D36 -> ANGELA MIREYA MONTENEGRO ROMERO | E46: =E36*8% -> 11.6 | F46: =F73-E46 -> 0.4 | H46: =F73/F36 -> 0.077419355 | I46: =BASE!U15-BASE!U6 -> 0
...
