Workbook

Sheet Activas
A1: OBJETIVO ACTIVIDAD GV ARTE C | D1: 12
N2: 1152 | P2: 1322
P3: 0.27628004 | Q3: 17301 | S3: 0.6231 | T3: 0.54514437
B5: Cod. Sector | C5: Sector | D5: Clúster | E5: Nombre GN | F5: Disp. Finales C11 | G5: Obj. Saldo C12 | H5: Disp. PY C12 | L5: Saldo Direccional | M5: I3 C11 | N5: Obj. Inicios | O5: Indisponibles Inic. C12 | P5: Obj. Recuperos | Q5: Obj. Activas Frecuentes | R5: Objetivo Activas | S5: Objetivo Actividad | T5: Objetivo AF | U5: %Cump Disp C11 | W5: falta
B6: 700000021 | C6: Sector COLORES Karen | D6: Bogotá_Norte-Centro | E6: Karen Esperanza Contreras Patiño | F6: 2098 | G6: 13 | H6: 2111 | K6: 1.0071191 | L6: 24 | M6: 150 | N6: 54 | O6: 330 | P6: 120 | Q6: 1105 | R6: 1279 | S6: 0.60587399 | T6: 0.5234486 | U6: 1.0023878 | V6: 1279 | W6: -16 | X6: 0 | Y6: 0.064677623 | Z6: 0
B7: 700000454 | C7: Sector ABÁNICO Judy | D7: Bogotá_Norte-Centro | E7: Judy Daza | F7: 1850 | G7: 12 | H7: 1862 | K7: 0.99477261 | L7: 53 | M7: 110 | N7: 72 | O7: 326 | P7: 91 | Q7: 974 | R7: 1137 | S7: 0.61063373 | T7: 0.52309345 | U7: 0.97317201 | V7: 1137 | W7: 12 | X7: 0 | Y7: 0.057496839 | Z7: 0
B8: 700000022 | C8: Sector BRILLO Kelly | D8: Bogotá_Norte-Centro | E8: Kelly Lorena Mesa | F8: 1800 | G8: 13 | H8: 1813 | K8: 0.97553191 | L8: 34 | M8: 120 | N8: 45 | O8: 259 | P8: 109 | Q8: 953 | R8: 1107 | S8: 0.61059018 | T8: 0.5256481 | U8: 0.96411355 | V8: 1107 | W8: -23 | X8: 0 | Y8: 0.055979772 | Z8: 0
B9: 700000457 | C9: Sector PINCEL Iliana | D9: Bogotá_Norte-Centro | E9: Iliana Alexandra Riaño Enciso | F9: 1850 | G9: 12 | H9: 1862 | K9: 0.9611399 | L9: 5 | M9: 120 | N9: 49 | O9: 241 | P9: 76 | Q9: 1012 | R9: 1137 | S9: 0.61063373 | T9: 0.54350161 | U9: 0.9645464 | V9: 1137 | W9: -5 | X9: 0 | Y9: 0.057496839 | Z9: 0
B10: 700000455 | C10: Sector ESPLENDOR Sandra | D10: Bogotá_Norte-Centro | E10: Sandra Cecilia Fuentes | F10: 1674 | G10: 13 | H10: 1687 | K10: 1.0563817 | L10: 31 | M10: 95 | N10: 65 | O10: 267 | P10: 61 | Q10: 896 | R10: 1022 | S10: 0.60580913 | T10: 0.53112033 | U10: 1.0455965 | V10: 1022 | W10: 44 | X10: 0 | Y10: 0.051681416 | Z10: 0
B11: 700000023 | C11: Sector POESIA Yulieth | D11: Bogotá_Norte-Centro | E11: Yenny Yulieth Campo Murillo | F11: 1973 | G11: 12 | H11: 1985 | K11: 0.96026807 | L11: 33 | M11: 117 | N11: 65 | O11: 325 | P11: 85 | Q11: 1066 | R11: 1216 | S11: 0.61259446 | T11: 0.53702771 | U11: 0.90633609 | V11: 1216 | W11: -26 | X11: 0 | Y11: 0.061491783 | Z11: 0
B12: 700000456 | C12: Sector ACUARELA Yeimi | D12: Bogotá_Norte-Centro | E12: Yeimi Patricia Rodriguez | F12: 2101 | G12: 12 | H12: 2113 | K12: 1.0300825 | L12: 22 | M12: 137 | N12: 69 | O12: 292 | P12: 90 | Q12: 1142 | R12: 1301 | S12: 0.61571226 | T12: 0.5404638 | U12: 1.0253782 | V12: 1301 | W12: 2 | X12: 0 | Y12: 0.065790139 | Z12: 0
B13: 700000459 | C13: Sector MATICES Clery | D13: Poblaciones Cundinamarca_Facatativá/Madrid | E13: Clery Enith Cuellar Rojas | F13: 1233 | G13: 13 | H13: 1246 | K13: 1.0614996 | L13: 27 | M13: 78 | N13: 58 | O13: 189 | P13: 47 | Q13: 663 | R13: 768 | S13: 0.61637239 | T13: 0.53210273 | U13: 1.1261426 | V13: 768 | W13: -27 | X13: 0 | Y13: 0.038836915 | Z13: 0
B14: 700000458 | C14: Sector LIENZO Ángela | D14: Poblaciones Cundinamarca_Chía | E14: Ángela Rios | F14: 1439 | G14: 13 | H14: 1452 | K14: 1.0259285 | L14: 25 | M14: 78 | N14: 48 | O14: 198 | P14: 55 | Q14: 800 | R14: 903 | S14: 0.62190083 | T14: 0.55096419 | U14: 1.0176803 | V14: 903 | W14: -64 | X14: 0 | Y14: 0.045663717 | Z14: 0
B15: 700000232 | C15: Sector EXPRESIÓN Nayibe | D15: Poblaciones Cundinamarca_Facatativá/Madrid | E15: Nayibe Esmeralda Pulido | F15: 1255 | G15: 13 | H15: 1268 | K15: 0.97326203 | L15: 19 | M15: 81 | N15: 48 | O15: 203 | P15: 52 | Q15: 689 | R15: 789 | S15: 0.62223975 | T15: 0.54337539 | U15: 0.9691358 | V15: 789 | W15: 0 | X15: 0 | Y15: 0.039898862 | Z15: 0
B16: 700000245 | C16: Sector ARTESANÍA Fernanda | D16: Boyacá_Chiquinquirá Boyacá | E16: Fernanda Peña | F16: 1548 | G16: 13 | H16: 1561 | K16: 0.95897122 | L16: 18 | M16: 102 | N16: 45 | O16: 226 | P16: 75 | Q16: 859 | R16: 979 | S16: 0.62716208 | T16: 0.55028828 | U16: 0.95555556 | V16: 979 | W16: -29 | X16: 0 | Y16: 0.049506953 | Z16: 0
B17: 700000466 | C17: Sector EMOCIONES Dolly | D17: Boyacá_DuitamaBoyacá | E17: Dolly Yanine Parra Velandia | F17: 1472 | G17: 12 | H17: 1484 | K17: 1.0252387 | L17: 31 | M17: 77 | N17: 46 | O17: 182 | P17: 62 | Q17: 815 | R17: 923 | S17: 0.62196765 | T17: 0.54919137 | U17: 1.0123796 | V17: 923 | W17: -2 | X17: 0 | Y17: 0.046675095 | Z17: 0
... B25: 700000423 | C25: Sector ARMONÍA Claudia | D25: Sucre_Sincelejo | E25: Claudia Patricia Benitez | F25: 1699 | G25: 13 | H25: 1712 | K25: 1.058895 | L25: 45 | M25: 105 | N25: 80 | O25: 295 | P25: 70 | Q25: 933 | R25: 1083 | S25: 0.63259346 | T25: 0.54497664 | U25: 1.0397797 | V25: 1083 | W25: -31 | X25: 0 | Y25: 0.054766119 | Z25: 0
B26: 700000003 | C26: Gerencia de Ventas Arte | F26: 31486 | G26: 250 | H26: 31736 | L26: 523 | M26: 1955 | N26: 1155 | O26: 4785 | P26: 1323 | Q26: 17297 | R26: 19775 | S26: 0.6231094 | T26: 0.54502773
N27: 3 | P27: -1
Q28: Padrón | R28: 19775
Q29: Check | R29: OK
Q30: Diferencia | R30: 0
B31: 1612
B32: 0.652
B33: 1051.024 | C33: 85.976
B34: 4.6010852e+08
B35: 437771.66 | C35: 0.078948934
C36: 32033.662

Sheet Disponibles
O1: =AB6/V6 -> 0.69152083 | P1: =AC6/W6 -> 0.37271994 | Q1: =AD6/X6 -> 0.35257732 | R1: =AE6/Y6 -> 0.35038363 | S1: =AF6/Z6 -> 0.26041019 | T1: =AG6/AA6 -> 0.17936118 | X1: OK | AA1: Real | AH1: OK
AA2: OBJ | AB2: 0.6916 | AC2: 0.3733 | AD2: 0.352 | AE2: 0.3517 | AF2: 0.2594 | AG2: 0.178
B4: =Activas!$D$1 -> 12 | F4: OK | G4: OK | H4: OK | I4: OK | J4: OK | K4: OK | L4: OK | M4: OK | O4: =O6/$L$6 -> 0.19219594 | P4: =P6/$L$6 -> 0.12140336 | Q4: =Q6/$L$6 -> 0.068668187 | R4: =R6/$L$6 -> 0.039676341 | S4: =S6/$L$6 -> 0.037177044 | T4: =T6/$L$6 -> 0.031303696 | V4: INACTIVAS INICIALES | AB4: DEBE ACTIVAR
B5: Cod. Sector | C5: Sector | D5: Clúster | E5: GN | F5: ="Disp Fin 2026"&$B$4-1 -> Disp Fin 202611 | G5: ="I3 Fin C"&$B$4-1 -> I3 Fin C11 | H5: ="Disp inicial 2026"&$B$4 -> Disp inicial 202612 | I5: ="Saldo Obj 2026"&$B$4 -> Saldo Obj 202612 | J5: Inicios Obj | K5: Recuperos Obj | L5: ="Disp Real 2026"&$B$4&" (Proy)" -> Disp Real 202612 (Proy) | M5: ="Disp Obj 2026"&$B$4 -> Disp Obj 202612 | N5: Cumpl % | O5: Inac 1 Obj | P5: Inac 2 Obj | Q5: Inac 3 Obj | R5: Inac 4 Obj | S5: Inac 5 Obj | T5: Inac 6 Obj | V5: I1 | W5: I2 | X5: I3 | Y5: I4 | Z5: I5 | AA5: I6 | AB5: I1 | AC5: I2 | AD5: I3 | AE5: I4 | AF5: I5 | AG5: I6 | AI5: Debe activar | AJ5: Debe Recuperar | AM5: ="Activas Obj C"&$B$4 -> Activas Obj C12 | AN5: Dif "Debe Activar" | AO5: Peso i1 | AP5: Peso i2 | AQ5: i1 Ajustar | AR5: i2 Ajustar | AT5: Recuperos Obj | AU5: Dif "Debe Recuperar" | AV5: i4 Ajustar | AW5: i5 Ajustar | AY5: Recuperos | AZ5: Activas | BA5: Activas Frecuentes
B6: 700000003 | C6: Gerencia de Ventas Arte | D6: =D5 -> Clúster | E6: Gerente de Negocio | F6: =SUM(F7:F29) -> 31486 | G6: =SUM(G7:G29) -> 1955 | H6: =SUM(H7:H29) -> 29531 | I6: =SUM(I7:I29) -> 250 | J6: =SUM(J7:J29) -> 1155 | K6: =SUM(K7:K29) -> 1323 | L6: =SUM(L7:L29) -> 32009 | M6: =SUM(M7:M29) -> 31728 | N6: =IFERROR(L6/M6,"") -> 1.0088565 | O6: =SUM(O7:O29) -> 6152 | P6: =SUM(P7:P29) -> 3886 | Q6: =SUM(Q7:Q29) -> 2198 | R6: =SUM(R7:R29) -> 1270 | S6: =SUM(S7:S29) -> 1190 | T6: =SUM(T7:T29) -> 1002 | V6: =SUM(V7:V26) -> 19943 | W6: =SUM(W7:W26) -> 6195 | X6: =SUM(X7:X26) -> 3395 | Y6: =SUM(Y7:Y26) -> 1955 | Z6: =SUM(Z7:Z26) -> 1609 | AA6: =SUM(AA7:AA26) -> 1221 | AB6: =SUM(AB7:AB29) -> 13791 | AC6: =SUM(AC7:AC29) -> 2309 | AD6: =SUM(AD7:AD29) -> 1197 | AE6: =SUM(AE7:AE29) -> 685 | AF6: =SUM(AF7:AF29) -> 419 | AG6: =SUM(AG7:AG29) -> 219 | AI6: =SUM(AI7:AI29) -> 19775 | AJ6: =SUM(AJ7:AJ29) -> 1323 | AM6: =IFERROR(SUM(AM7:AM29),"") -> 19775 | AN6: =SUM(AN7:AN29) -> -4 | AO6: =O6/L6 -> 0.19219594 | AP6: =P6/L6 -> 0.12140336 | AQ6: =SUM(AQ7:AQ25) -> 1 | AR6: =SUM(AR7:AR25) -> -1 | AT6: =SUM(AT7:AT29) -> 1323 | AU6: =SUM(AU7:AU29) -> -1 | AV6: =SUM(AV7:AV29) -> -1 | AW6: =SUM(AW7:AW29) -> 0 | AY6: =Activas!P26 -> 1323 | AZ6: =Activas!R26 -> 19775 | BA6: =Activas!Q26 -> 17297 | BC6: =AB6/V6 -> 0.69152083 | BD6: =AC6/W6 -> 0.37271994 | BE6: =AD6/X6 -> 0.35257732 | BF6: =AE6/Y6 -> 0.35038363 | BG6: =AF6/Z6 -> 0.26041019 | BH6: =AG6/AA6 -> 0.17936118
B7: 700000021 | C7: Sector COLORES Karen | D7: Bogotá_Norte-Centro | E7: Karen Esperanza Contreras Patiño | F7: =VLOOKUP(B7,Activas!$B$5:$F$26,5,FALSE) -> 2098 | G7: =_xlfn.XLOOKUP(B7,Activas!B:B,Activas!M:M) -> 150 | H7: =F7-G7 -> 1948 | I7: =_xlfn.XLOOKUP(B7,Activas!$B$6:$B$25,Activas!$G$6:$G$25) -> 13 | J7: =_xlfn.XLOOKUP(B7,Activas!B:B,Activas!N:N) -> 54 | K7: =_xlfn.XLOOKUP(B7,Activas!B:B,Activas!P:P) -> 120 | L7: =H7+J7+K7 -> 2122 | M7: =INDEX([1]Base!$V:$V,MATCH(B7,[1]Base!$C:$C,0)) -> 2107 | N7: =IFERROR(L7/M7,"") -> 1.0071191 | O7: =V7-AB7 -> 403 | P7: =W7-AC7 -> 282 | Q7: =X7-AD7 -> 159 | R7: =Y7-AE7 -> 84 | S7: =Z7-AF7 -> 72 | T7: =AA7-AG7 -> 54 | V7: =INDEX([2]TD!C:C,MATCH($B7,[2]TD!$A:$A,0)) -> 1270 | W7: =INDEX([2]TD!D:D,MATCH($B7,[2]TD!$A:$A,0)) -> 433 | X7: =INDEX([2]TD!E:E,MATCH($B7,[2]TD!$A:$A,0)) -> 246 | Y7: =INDEX([2]TD!F:F,MATCH($B7,[2]TD!$A:$A,0)) -> 150 | Z7: =INDEX([2]TD!G:G,MATCH($B7,[2]TD!$A:$A,0)) -> 114 | AA7: =INDEX([2]TD!H:H,MATCH($B7,[2]TD!$A:$A,0)) -> 66 | AB7: =ROUND(V7*AB$2,0)+AQ7 -> 867 | AC7: =ROUND(W7*AC$2,0)+AR7 -> 151 | AD7: =ROUND(X7*AD$2,0) -> 87 | AE7: =ROUND(Y7*AE$2,0)+AV7 -> 66 | AF7: =ROUND(Z7*AF$2,0)+AW7 -> 42 | AG7: =ROUND(AA7*AG$2,0) -> 12 | AH7: =SUM(AB7:AD7) -> 1105 | AI7: =SUM(AB7:AG7)+J7 -> 1279 | AJ7: =SUM(AE7:AG7) -> 120 | AM7: =_xlfn.XLOOKUP(B7,Activas!B:B,Activas!R:R) -> 1279 | AN7: -22 | AO7: =O7/L7 -> 0.18991517 | AP7: =P7/L7 -> 0.1328935 | AQ7: =ROUND(AN7*50%,0) -> -11 | AR7: =AN7-AQ7 -> -11 | AS7: =AM7-AI7 -> 0 | AT7: =K7 -> 120 | AU7: 25 | AV7: =ROUND(AU7*50%,0) -> 13 | AW7: =AU7-AV7 -> 12 | AX7: =AT7-AJ7 -> 0 | AY7: =SUM(AE6:AG6) -> 1323 | AZ7: =SUM(AB6:AG6)+J6 -> 19775 | BA7: =SUM(AB6:AD6) -> 17297 | BC7: =AB7/V7 -> 0.68267717 | BD7: =AC7/W7 -> 0.34872979 | BE7: =AD7/X7 -> 0.35365854 | BF7: =AE7/Y7 -> 0.44 | BG7: =AF7/Z7 -> 0.36842105 | BH7: =AG7/AA7 -> 0.18181818
B8: 700000454 | C8: Sector ABÁNICO Judy | D8: Bogotá_Norte-Centro | E8: Judy Daza | F8: =VLOOKUP(B8,Activas!$B$5:$F$26,5,FALSE) -> 1850 | G8: =_xlfn.XLOOKUP(B8,Activas!B:B,Activas!M:M) -> 110 | H8: =F8-G8 -> 1740 | I8: =_xlfn.XLOOKUP(B8,Activas!$B$6:$B$25,Activas!$G$6:$G$25) -> 12 | J8: =_xlfn.XLOOKUP(B8,Activas!B:B,Activas!N:N) -> 72 | K8: =_xlfn.XLOOKUP(B8,Activas!B:B,Activas!P:P) -> 91 | L8: =H8+J8+K8 -> 1903 | M8: =INDEX([1]Base!$V:$V,MATCH(B8,[1]Base!$C:$C,0)) -> 1913 | N8: =IFERROR(L8/M8,"") -> 0.99477261 | O8: =V8-AB8 -> 357 | P8: =W8-AC8 -> 272 | Q8: =X8-AD8 -> 137 | R8: =Y8-AE8 -> 69 | S8: =Z8-AF8 -> 94 | T8: =AA8-AG8 -> 72 | V8: =INDEX([2]TD!C:C,MATCH($B8,[2]TD!$A:$A,0)) -> 1116 | W8: =INDEX([2]TD!D:D,MATCH($B8,[2]TD!$A:$A,0)) -> 413 | X8: =INDEX([2]TD!E:E,MATCH($B8,[2]TD!$A:$A,0)) -> 211 | Y8: =INDEX([2]TD!F:F,MATCH($B8,[2]TD!$A:$A,0)) -> 110 | Z8: =INDEX([2]TD!G:G,MATCH($B8,[2]TD!$A:$A,0)) -> 129 | AA8: =INDEX([2]TD!H:H,MATCH($B8,[2]TD!$A:$A,0)) -> 87 | AB8: =ROUND(V8*AB$2,0)+AQ8 -> 759 | AC8: =ROUND(W8*AC$2,0)+AR8 -> 141 | AD8: =ROUND(X8*AD$2,0) -> 74 | AE8: =ROUND(Y8*AE$2,0)+AV8 -> 41 | AF8: =ROUND(Z8*AF$2,0)+AW8 -> 35 | AG8: =ROUND(AA8*AG$2,0) -> 15 | AH8: =SUM(AB8:AD8) -> 974 | AI8: =SUM(AB8:AG8)+J8 -> 1137 | AJ8: =SUM(AE8:AG8) -> 91 | AM8: =_xlfn.XLOOKUP(B8,Activas!B:B,Activas!R:R) -> 1137 | AN8: -26 | AO8: =O8/L8 -> 0.18759853 | AP8: =P8/L8 -> 0.14293221 | AQ8: =ROUND(AN8*50%,0) -> -13 | AR8: =AN8-AQ8 -> -13 | AS8: =AM8-AI8 -> 0 | AT8: =K8 -> 91 | AU8: 4 | AV8: =ROUND(AU8*50%,0) -> 2 | AW8: =AU8-AV8 -> 2 | AX8: =AT8-AJ8 -> 0 | BC8: =AB8/V8 -> 0.68010753 | BD8: =AC8/W8 -> 0.34140436 | BE8: =AD8/X8 -> 0.3507109 | BF8: =AE8/Y8 -> 0.37272727 | BG8: =AF8/Z8 -> 0.27131783 | BH8: =AG8/AA8 -> 0.17241379
B9: 700000022 | C9: Sector BRILLO Kelly | D9: Bogotá_Norte-Centro | E9: Kelly Lorena Mesa | F9: =VLOOKUP(B9,Activas!$B$5:$F$26,5,FALSE) -> 1800 | G9: =_xlfn.XLOOKUP(B9,Activas!B:B,Activas!M:M) -> 120 | H9: =F9-G9 -> 1680 | I9: =_xlfn.XLOOKUP(B9,Activas!$B$6:$B$25,Activas!$G$6:$G$25) -> 13 | J9: =_xlfn.XLOOKUP(B9,Activas!B:B,Activas!N:N) -> 45 | K9: =_xlfn.XLOOKUP(B9,Activas!B:B,Activas!P:P) -> 109 | L9: =H9+J9+K9 -> 1834 | M9: =INDEX([1]Base!$V:$V,MATCH(B9,[1]Base!$C:$C,0)) -> 1880 | N9: =IFERROR(L9/M9,"") -> 0.97553191 | O9: =V9-AB9 -> 335 | P9: =W9-AC9 -> 243 | Q9: =X9-AD9 -> 149 | R9: =Y9-AE9 -> 60 | S9: =Z9-AF9 -> 46 | T9: =AA9-AG9 -> 44 | V9: =INDEX([2]TD!C:C,MATCH($B9,[2]TD!$A:$A,0)) -> 1070 | W9: =INDEX([2]TD!D:D,MATCH($B9,[2]TD!$A:$A,0)) -> 380 | X9: =INDEX([2]TD!E:E,MATCH($B9,[2]TD!$A:$A,0)) -> 230 | Y9: =INDEX([2]TD!F:F,MATCH($B9,[2]TD!$A:$A,0)) -> 120 | Z9: =INDEX([2]TD!G:G,MATCH($B9,[2]TD!$A:$A,0)) -> 86 | AA9: =INDEX([2]TD!H:H,MATCH($B9,[2]TD!$A:$A,0)) -> 53 | AB9: =ROUND(V9*AB$2,0)+AQ9 -> 735 | AC9: =ROUND(W9*AC$2,0)+AR9 -> 137 | AD9: =ROUND(X9*AD$2,0) -> 81 | AE9: =ROUND(Y9*AE$2,0)+AV9 -> 60 | AF9: =ROUND(Z9*AF$2,0)+AW9 -> 40 | AG9: =ROUND(AA9*AG$2,0) -> 9 | AH9: =SUM(AB9:AD9) -> 953 | AI9: =SUM(AB9:AG9)+J9 -> 1107 | AJ9: =SUM(AE9:AG9) -> 109 | AM9: =_xlfn.XLOOKUP(B9,Activas!B:B,Activas!R:R) -> 1107 | AN9: -10 | AO9: =O9/L9 -> 0.18266085 | AP9: =P9/L9 -> 0.13249727 | AQ9: =ROUND(AN9*50%,0) -> -5 | AR9: =AN9-AQ9 -> -5 | AS9: =AM9-AI9 -> 0 | AT9: =K9 -> 109 | AU9: 36 | AV9: =ROUND(AU9*50%,0) -> 18 | AW9: =AU9-AV9 -> 18 | AX9: =AT9-AJ9 -> 0 | BC9: =AB9/V9 -> 0.68691589 | BD9: =AC9/W9 -> 0.36052632 | BE9: =AD9/X9 -> 0.35217391 | BF9: =AE9/Y9 -> 0.5 | BG9: =AF9/Z9 -> 0.46511628 | BH9: =AG9/AA9 -> 0.16981132
B10: 700000457 | C10: Sector PINCEL Iliana | D10: Bogotá_Norte-Centro | E10: Iliana Alexandra Riaño Enciso | F10: =VLOOKUP(B10,Activas!$B$5:$F$26,5,FALSE) -> 1850 | G10: =_xlfn.XLOOKUP(B10,Activas!B:B,Activas!M:M) -> 120 | H10: =F10-G10 -> 1730 | I10: =_xlfn.XLOOKUP(B10,Activas!$B$6:$B$25,Activas!$G$6:$G$25) -> 12 | J10: =_xlfn.XLOOKUP(B10,Activas!B:B,Activas!N:N) -> 49 | K10: =_xlfn.XLOOKUP(B10,Activas!B:B,Activas!P:P) -> 76 | L10: =H10+J10+K10 -> 1855 | M10: =INDEX([1]Base!$V:$V,MATCH(B10,[1]Base!$C:$C,0)) -> 1930 | N10: =IFERROR(L10/M10,"") -> 0.9611399 | O10: =V10-AB10 -> 358 | P10: =W10-AC10 -> 230 | Q10: =X10-AD10 -> 130 | R10: =Y10-AE10 -> 74 | S10: =Z10-AF10 -> 47 | T10: =AA10-AG10 -> 44 | V10: =INDEX([2]TD!C:C,MATCH($B10,[2]TD!$A:$A,0)) -> 1163 | W10: =INDEX([2]TD!D:D,MATCH($B10,[2]TD!$A:$A,0)) -> 367 | X10: =INDEX([2]TD!E:E,MATCH($B10,[2]TD!$A:$A,0)) -> 200 | Y10: =INDEX([2]TD!F:F,MATCH($B10,[2]TD!$A:$A,0)) -> 120 | Z10: =INDEX([2]TD!G:G,MATCH($B10,[2]TD!$A:$A,0)) -> 67 | AA10: =INDEX([2]TD!H:H,MATCH($B10,[2]TD!$A:$A,0)) -> 54 | AB10: =ROUND(V10*AB$2,0)+AQ10 -> 805 | AC10: =ROUND(W10*AC$2,0)+AR10 -> 137 | AD10: =ROUND(X10*AD$2,0) -> 70 | AE10: =ROUND(Y10*AE$2,0)+AV10 -> 46 | AF10: =ROUND(Z10*AF$2,0)+AW10 -> 20 | AG10: =ROUND(AA10*AG$2,0) -> 10 | AH10: =SUM(AB10:AD10) -> 1012 | AI10: =SUM(AB10:AG10)+J10 -> 1137 | AJ10: =SUM(AE10:AG10) -> 76 | AM10: =_xlfn.XLOOKUP(B10,Activas!B:B,Activas!R:R) -> 1137 | AN10: 1 | AO10: =O10/L10 -> 0.19299191 | AP10: =P10/L10 -> 0.12398922 | AQ10: =ROUND(AN10*50%,0) -> 1 | AR10: =AN10-AQ10 -> 0 | AS10: =AM10-AI10 -> 0 | AT10: =K10 -> 76 | AU10: 7 | AV10: =ROUND(AU10*50%,0) -> 4 | AW10: =AU10-AV10 -> 3 | AX10: =AT10-AJ10 -> 0 | BC10: =AB10/V10 -> 0.69217541 | BD10: =AC10/W10 -> 0.373297 | BE10: =AD10/X10 -> 0.35 | BF10: =AE10/Y10 -> 0.38333333 | BG10: =AF10/Z10 -> 0.29850746 | BH10: =AG10/AA10 -> 0.18518519
B11: 700000455 | C11: Sector ESPLENDOR Carolina | D11: Bogotá_Norte-Centro | E11: Carolina Tangarife Tamayo | F11: =VLOOKUP(B11,Activas!$B$5:$F$26,5,FALSE) -> 1674 | G11: =_xlfn.XLOOKUP(B11,Activas!B:B,Activas!M:M) -> 95 | H11: =F11-G11 -> 1579 | I11: =_xlfn.XLOOKUP(B11,Activas!$B$6:$B$25,Activas!$G$6:$G$25) -> 13 | J11: =_xlfn.XLOOKUP(B11,Activas!B:B,Activas!N:N) -> 65 | K11: =_xlfn.XLOOKUP(B11,Activas!B:B,Activas!P:P) -> 61 | L11: =H11+J11+K11 -> 1705 | M11: =INDEX([1]Base!$V:$V,MATCH(B11,[1]Base!$C:$C,0)) -> 1614 | N11: =IFERROR(L11/M11,"") -> 1.0563817 | O11: =V11-AB11 -> 337 | P11: =W11-AC11 -> 215 | Q11: =X11-AD11 -> 131 | R11: =Y11-AE11 -> 68 | S11: =Z11-AF11 -> 75 | T11: =AA11-AG11 -> 63 | V11: =INDEX([2]TD!C:C,MATCH($B11,[2]TD!$A:$A,0)) -> 1053 | W11: =INDEX([2]TD!D:D,MATCH($B11,[2]TD!$A:$A,0)) -> 324 | X11: =INDEX([2]TD!E:E,MATCH($B11,[2]TD!$A:$A,0)) -> 202 | Y11: =INDEX([2]TD!F:F,MATCH($B11,[2]TD!$A:$A,0)) -> 95 | Z11: =INDEX([2]TD!G:G,MATCH($B11,[2]TD!$A:$A,0)) -> 95 | AA11: =INDEX([2]TD!H:H,MATCH($B11,[2]TD!$A:$A,0)) -> 77 | AB11: =ROUND(V11*AB$2,0)+AQ11 -> 716 | AC11: =ROUND(W11*AC$2,0)+AR11 -> 109 | AD11: =ROUND(X11*AD$2,0) -> 71 | AE11: =ROUND(Y11*AE$2,0)+AV11 -> 27 | AF11: =ROUND(Z11*AF$2,0)+AW11 -> 20 | AG11: =ROUND(AA11*AG$2,0) -> 14 | AH11: =SUM(AB11:AD11) -> 896 | AI11: =SUM(AB11:AG11)+J11 -> 1022 | AJ11: =SUM(AE11:AG11) -> 61 | AM11: =_xlfn.XLOOKUP(B11,Activas!B:B,Activas!R:R) -> 1022 | AN11: -24 | AO11: =O11/L11 -> 0.19765396 | AP11: =P11/L11 -> 0.12609971 | AQ11: =ROUND(AN11*50%,0) -> -12 | AR11: =AN11-AQ11 -> -12 | AS11: =AM11-AI11 -> 0 | AT11: =K11 -> 61 | AU11: -11 | AV11: =ROUND(AU11*50%,0) -> -6 | AW11: =AU11-AV11 -> -5 | AX11: =AT11-AJ11 -> 0 | AY11: =AY6-AY7 -> 0 | AZ11: =AZ6-AZ7 -> 0 | BA11: =BA6-BA7 -> 0 | BC11: =AB11/V11 -> 0.67996201 | BD11: =AC11/W11 -> 0.33641975 | BE11: =AD11/X11 -> 0.35148515 | BF11: =AE11/Y11 -> 0.28421053 | BG11: =AF11/Z11 -> 0.21052632 | BH11: =AG11/AA11 -> 0.18181818
B12: 700000023 | C12: Sector POESIA Yulieth | D12: Bogotá_Norte-Centro | E12: Yenny Yulieth Campo Murillo | F12: =VLOOKUP(B12,Activas!$B$5:$F$26,5,FALSE) -> 1973 | G12: =_xlfn.XLOOKUP(B12,Activas!B:B,Activas!M:M) -> 117 | H12: =F12-G12 -> 1856 | I12: =_xlfn.XLOOKUP(B12,Activas!$B$6:$B$25,Activas!$G$6:$G$25) -> 12 | J12: =_xlfn.XLOOKUP(B12,Activas!B:B,Activas!N:N) -> 65 | K12: =_xlfn.XLOOKUP(B12,Activas!B:B,Activas!P:P) -> 85 | L12: =H12+J12+K12 -> 2006 | M12: =INDEX([1]Base!$V:$V,MATCH(B12,[1]Base!$C:$C,0)) -> 2089 | N12: =IFERROR(L12/M12,"") -> 0.96026807 | O12: =V12-AB12 -> 360 | P12: =W12-AC12 -> 279 | Q12: =X12-AD12 -> 152 | R12: =Y12-AE12 -> 78 | S12: =Z12-AF12 -> 89 | T12: =AA12-AG12 -> 73 | V12: =INDEX([2]TD!C:C,MATCH($B12,[2]TD!$A:$A,0)) -> 1175 | W12: =INDEX([2]TD!D:D,MATCH($B12,[2]TD!$A:$A,0)) -> 447 | X12: =INDEX([2]TD!E:E,MATCH($B12,[2]TD!$A:$A,0)) -> 235 | Y12: =INDEX([2]TD!F:F,MATCH($B12,[2]TD!$A:$A,0)) -> 117 | Z12: =INDEX([2]TD!G:G,MATCH($B12,[2]TD!$A:$A,0)) -> 119 | AA12: =INDEX([2]TD!H:H,MATCH($B12,[2]TD!$A:$A,0)) -> 89 | AB12: =ROUND(V12*AB$2,0)+AQ12 -> 815 | AC12: =ROUND(W12*AC$2,0)+AR12 -> 168 | AD12: =ROUND(X12*AD$2,0) -> 83 | AE12: =ROUND(Y12*AE$2,0)+AV12 -> 39 | AF12: =ROUND(Z12*AF$2,0)+AW12 -> 30 | AG12: =ROUND(AA12*AG$2,0) -> 16 | AH12: =SUM(AB12:AD12) -> 1066 | AI12: =SUM(AB12:AG12)+J12 -> 1216 | AJ12: =SUM(AE12:AG12) -> 85 | AM12: =_xlfn.XLOOKUP(B12,Activas!B:B,Activas!R:R) -> 1216 | AN12: 3 | AO12: =O12/L12 -> 0.17946162 | AP12: =P12/L12 -> 0.13908275 | AQ12: =ROUND(AN12*50%,0) -> 2 | AR12: =AN12-AQ12 -> 1 | AS12: =AM12-AI12 -> 0 | AT12: =K12 -> 85 | AU12: -3 | AV12: =ROUND(AU12*50%,0) -> -2 | AW12: =AU12-AV12 -> -1 | AX12: =AT12-AJ12 -> 0 | BC12: =AB12/V12 -> 0.69361702 | BD12: =AC12/W12 -> 0.37583893 | BE12: =AD12/X12 -> 0.35319149 | BF12: =AE12/Y12 -> 0.33333333 | BG12: =AF12/Z12 -> 0.25210084 | BH12: =AG12/AA12 -> 0.17977528
B13: 700000456 | C13: Sector ACUARELA Yeimi | D13: Bogotá_Norte-Centro | E13: Yeimi Patricia Rodriguez | F13: =VLOOKUP(B13,Activas!$B$5:$F$26,5,FALSE) -> 2101 | G13: =_xlfn.XLOOKUP(B13,Activas!B:B,Activas!M:M) -> 137 | H13: =F13-G13 -> 1964 | I13: =_xlfn.XLOOKUP(B13,Activas!$B$6:$B$25,Activas!$G$6:$G$25) -> 12 | J13: =_xlfn.XLOOKUP(B13,Activas!B:B,Activas!N:N) -> 69 | K13: =_xlfn.XLOOKUP(B13,Activas!B:B,Activas!P:P) -> 90 | L13: =H13+J13+K13 -> 2123 | M13: =INDEX([1]Base!$V:$V,MATCH(B13,[1]Base!$C:$C,0)) -> 2061 | N13: =IFERROR(L13/M13,"") -> 1.0300825 | O13: =V13-AB13 -> 403 | P13: =W13-AC13 -> 266 | Q13: =X13-AD13 -> 153 | R13: =Y13-AE13 -> 85 | S13: =Z13-AF13 -> 62 | T13: =AA13-AG13 -> 55 | V13: =INDEX([2]TD!C:C,MATCH($B13,[2]TD!$A:$A,0)) -> 1304 | W13: =INDEX([2]TD!D:D,MATCH($B13,[2]TD!$A:$A,0)) -> 424 | X13: =INDEX([2]TD!E:E,MATCH($B13,[2]TD!$A:$A,0)) -> 236 | Y13: =INDEX([2]TD!F:F,MATCH($B13,[2]TD!$A:$A,0)) -> 137 | Z13: =INDEX([2]TD!G:G,MATCH($B13,[2]TD!$A:$A,0)) -> 88 | AA13: =INDEX([2]TD!H:H,MATCH($B13,[2]TD!$A:$A,0)) -> 67 | AB13: =ROUND(V13*AB$2,0)+AQ13 -> 901 | AC13: =ROUND(W13*AC$2,0)+AR13 -> 158 | AD13: =ROUND(X13*AD$2,0) -> 83 | AE13: =ROUND(Y13*AE$2,0)+AV13 -> 52 | AF13: =ROUND(Z13*AF$2,0)+AW13 -> 26 | AG13: =ROUND(AA13*AG$2,0) -> 12 | AH13: =SUM(AB13:AD13) -> 1142 | AI13: =SUM(AB13:AG13)+J13 -> 1301 | AJ13: =SUM(AE13:AG13) -> 90 | AM13: =_xlfn.XLOOKUP(B13,Activas!B:B,Activas!R:R) -> 1301 | AN13: -1 | AO13: =O13/L13 -> 0.18982572 | AP13: =P13/L13 -> 0.12529439 | AQ13: =ROUND(AN13*50%,0) -> -1 | AR13: =AN13-AQ13 -> 0 | AS13: =AM13-AI13 -> 0 | AT13: =K13 -> 90 | AU13: 7 | AV13: =ROUND(AU13*50%,0) -> 4 | AW13: =AU13-AV13 -> 3 | AX13: =AT13-AJ13 -> 0 | BC13: =AB13/V13 -> 0.69095092 | BD13: =AC13/W13 -> 0.37264151 | BE13: =AD13/X13 -> 0.35169492 | BF13: =AE13/Y13 -> 0.37956204 | BG13: =AF13/Z13 -> 0.29545455 | BH13: =AG13/AA13 -> 0.17910448
B14: 700000281 | C14: Sector PICASSO Regina | D14: Poblaciones córdoba_Lórica | E14: Regina Isabel Peñate Argumedo | F14: =VLOOKUP(B14,Activas!$B$5:$F$26,5,FALSE) -> 1454 | G14: =_xlfn.XLOOKUP(B14,Activas!B:B,Activas!M:M) -> 79 | H14: =F14-G14 -> 1375 | I14: =_xlfn.XLOOKUP(B14,Activas!$B$6:$B$25,Activas!$G$6:$G$25) -> 12 | J14: =_xlfn.XLOOKUP(B14,Activas!B:B,Activas!N:N) -> 61 | K14: =_xlfn.XLOOKUP(B14,Activas!B:B,Activas!P:P) -> 49 | L14: =H14+J14+K14 -> 1485 | M14: =INDEX([1]Base!$V:$V,MATCH(B14,[1]Base!$C:$C,0)) -> 1410 | N14: =IFERROR(L14/M14,"") -> 1.0531915 | O14: =V14-AB14 -> 302 | P14: =W14-AC14 -> 154 | Q14: =X14-AD14 -> 94 | R14: =Y14-AE14 -> 55 | S14: =Z14-AF14 -> 61 | T14: =AA14-AG14 -> 40 | V14: =INDEX([2]TD!C:C,MATCH($B14,[2]TD!$A:$A,0)) -> 983 | W14: =INDEX([2]TD!D:D,MATCH($B14,[2]TD!$A:$A,0)) -> 247 | X14: =INDEX([2]TD!E:E,MATCH($B14,[2]TD!$A:$A,0)) -> 145 | Y14: =INDEX([2]TD!F:F,MATCH($B14,[2]TD!$A:$A,0)) -> 79 | Z14: =INDEX([2]TD!G:G,MATCH($B14,[2]TD!$A:$A,0)) -> 77 | AA14: =INDEX([2]TD!H:H,MATCH($B14,[2]TD!$A:$A,0)) -> 49 | AB14: =ROUND(V14*AB$2,0)+AQ14 -> 681 | AC14: =ROUND(W14*AC$2,0)+AR14 -> 93 | AD14: =ROUND(X14*AD$2,0) -> 51 | AE14: =ROUND(Y14*AE$2,0)+AV14 -> 24 | AF14: =ROUND(Z14*AF$2,0)+AW14 -> 16 | AG14: =ROUND(AA14*AG$2,0) -> 9 | AH14: =SUM(AB14:AD14) -> 825 | AI14: =SUM(AB14:AG14)+J14 -> 935 | AJ14: =SUM(AE14:AG14) -> 49 | AM14: =_xlfn.XLOOKUP(B14,Activas!B:B,Activas!R:R) -> 935 | AN14: 2 | AO14: =O14/L14 -> 0.203367 | AP14: =P14/L14 -> 0.1037037 | AQ14: =ROUND(AN14*50%,0) -> 1 | AR14: =AN14-AQ14 -> 1 | AS14: =AM14-AI14 -> 0 | AT14: =K14 -> 49 | AU14: -8 | AV14: =ROUND(AU14*50%,0) -> -4 | AW14: =AU14-AV14 -> -4 | AX14: =AT14-AJ14 -> 0 | BC14: =AB14/V14 -> 0.69277721 | BD14: =AC14/W14 -> 0.37651822 | BE14: =AD14/X14 -> 0.35172414 | BF14: =AE14/Y14 -> 0.30379747 | BG14: =AF14/Z14 -> 0.20779221 | BH14: =AG14/AA14 -> 0.18367347
B15: 700000254 | C15: Sector CREATIVIDAD Yomaira | D15: Poblaciones córdoba_Tierralta | E15: Yomaira Estela Doria Ramos | F15: =VLOOKUP(B15,Activas!$B$5:$F$26,5,FALSE) -> 1153 | G15: =_xlfn.XLOOKUP(B15,Activas!B:B,Activas!M:M) -> 76 | H15: =F15-G15 -> 1077 | I15: =_xlfn.XLOOKUP(B15,Activas!$B$6:$B$25,Activas!$G$6:$G$25) -> 12 | J15: =_xlfn.XLOOKUP(B15,Activas!B:B,Activas!N:N) -> 49 | K15: =_xlfn.XLOOKUP(B15,Activas!B:B,Activas!P:P) -> 36 | L15: =H15+J15+K15 -> 1162 | M15: =INDEX([1]Base!$V:$V,MATCH(B15,[1]Base!$C:$C,0)) -> 1226 | N15: =IFERROR(L15/M15,"") -> 0.94779772 | O15: =V15-AB15 -> 229 | P15: =W15-AC15 -> 105 | Q15: =X15-AD15 -> 79 | R15: =Y15-AE15 -> 56 | S15: =Z15-AF15 -> 45 | T15: =AA15-AG15 -> 48 | V15: =INDEX([2]TD!C:C,MATCH($B15,[2]TD!$A:$A,0)) -> 773 | W15: =INDEX([2]TD!D:D,MATCH($B15,[2]TD!$A:$A,0)) -> 182 | X15: =INDEX([2]TD!E:E,MATCH($B15,[2]TD!$A:$A,0)) -> 122 | Y15: =INDEX([2]TD!F:F,MATCH($B15,[2]TD!$A:$A,0)) -> 76 | Z15: =INDEX([2]TD!G:G,MATCH($B15,[2]TD!$A:$A,0)) -> 51 | AA15: =INDEX([2]TD!H:H,MATCH($B15,[2]TD!$A:$A,0)) -> 58 | AB15: =ROUND(V15*AB$2,0)+AQ15 -> 544 | AC15: =ROUND(W15*AC$2,0)+AR15 -> 77 | AD15: =ROUND(X15*AD$2,0) -> 43 | AE15: =ROUND(Y15*AE$2,0)+AV15 -> 20 | AF15: =ROUND(Z15*AF$2,0)+AW15 -> 6 | AG15: =ROUND(AA15*AG$2,0) -> 10 | AH15: =SUM(AB15:AD15) -> 664 | AI15: =SUM(AB15:AG15)+J15 -> 749 | AJ15: =SUM(AE15:AG15) -> 36 | AM15: =_xlfn.XLOOKUP(B15,Activas!B:B,Activas!R:R) -> 749 | AN15: 18 | AO15: =O15/L15 -> 0.19707401 | AP15: =P15/L15 -> 0.090361446 | AQ15: =ROUND(AN15*50%,0) -> 9 | AR15: =AN15-AQ15 -> 9 | AS15: =AM15-AI15 -> 0 | AT15: =K15 -> 36 | AU15: -14 | AV15: =ROUND(AU15*50%,0) -> -7 | AW15: =AU15-AV15 -> -7 | AX15: =AT15-AJ15 -> 0 | BC15: =AB15/V15 -> 0.70375162 | BD15: =AC15/W15 -> 0.42307692 | BE15: =AD15/X15 -> 0.35245902 | BF15: =AE15/Y15 -> 0.26315789 | BG15: =AF15/Z15 -> 0.11764706 | BH15: =AG15/AA15 -> 0.17241379
B16: 700000098 | C16: Sector MOSAICO Julieth | D16: Montería | E16: Judith Julieth Castrillon Perez | F16: =VLOOKUP(B16,Activas!$B$5:$F$26,5,FALSE) -> 1190 | G16: =_xlfn.XLOOKUP(B16,Activas!B:B,Activas!M:M) -> 65 | H16: =F16-G16 -> 1125 | I16: =_xlfn.XLOOKUP(B16,Activas!$B$6:$B$25,Activas!$G$6:$G$25) -> 12 | J16: =_xlfn.XLOOKUP(B16,Activas!B:B,Activas!N:N) -> 46 | K16: =_xlfn.XLOOKUP(B16,Activas!B:B,Activas!P:P) -> 39 | L16: =H16+J16+K16 -> 1210 | M16: =INDEX([1]Base!$V:$V,MATCH(B16,[1]Base!$C:$C,0)) -> 1148 | N16: =IFERROR(L16/M16,"") -> 1.054007 | O16: =V16-AB16 -> 237 | P16: =W16-AC16 -> 139 | Q16: =X16-AD16 -> 65 | R16: =Y16-AE16 -> 41 | S16: =Z16-AF16 -> 22 | T16: =AA16-AG16 -> 30 | V16: =INDEX([2]TD!C:C,MATCH($B16,[2]TD!$A:$A,0)) -> 791 | W16: =INDEX([2]TD!D:D,MATCH($B16,[2]TD!$A:$A,0)) -> 233 | X16: =INDEX([2]TD!E:E,MATCH($B16,[2]TD!$A:$A,0)) -> 101 | Y16: =INDEX([2]TD!F:F,MATCH($B16,[2]TD!$A:$A,0)) -> 65 | Z16: =INDEX([2]TD!G:G,MATCH($B16,[2]TD!$A:$A,0)) -> 30 | AA16: =INDEX([2]TD!H:H,MATCH($B16,[2]TD!$A:$A,0)) -> 37 | AB16: =ROUND(V16*AB$2,0)+AQ16 -> 554 | AC16: =ROUND(W16*AC$2,0)+AR16 -> 94 | AD16: =ROUND(X16*AD$2,0) -> 36 | AE16: =ROUND(Y16*AE$2,0)+AV16 -> 24 | AF16: =ROUND(Z16*AF$2,0)+AW16 -> 8 | AG16: =ROUND(AA16*AG$2,0) -> 7 | AH16: =SUM(AB16:AD16) -> 684 | AI16: =SUM(AB16:AG16)+J16 -> 769 | AJ16: =SUM(AE16:AG16) -> 39 | AM16: =_xlfn.XLOOKUP(B16,Activas!B:B,Activas!R:R) -> 769 | AN16: 14 | AO16: =O16/L16 -> 0.19586777 | AP16: =P16/L16 -> 0.11487603 | AQ16: =ROUND(AN16*50%,0) -> 7 | AR16: =AN16-AQ16 -> 7 | AS16: =AM16-AI16 -> 0 | AT16: =K16 -> 39 | AU16: 1 | AV16: =ROUND(AU16*50%,0) -> 1 | AW16: =AU16-AV16 -> 0 | AX16: =AT16-AJ16 -> 0 | BC16: =AB16/V16 -> 0.70037927 | BD16: =AC16/W16 -> 0.40343348 | BE16: =AD16/X16 -> 0.35643564 | BF16: =AE16/Y16 -> 0.36923077 | BG16: =AF16/Z16 -> 0.26666667 | BH16: =AG16/AA16 -> 0.18918919
B17: 700000133 | C17: Sector INSPIRACIÓN Vanesa | D17: Montería | E17: Katherine Vanesa Gomez Coronado | F17: =VLOOKUP(B17,Activas!$B$5:$F$26,5,FALSE) -> 1084 | G17: =_xlfn.XLOOKUP(B17,Activas!B:B,Activas!M:M) -> 55 | H17: =F17-G17 -> 1029 | I17: =_xlfn.XLOOKUP(B17,Activas!$B$6:$B$25,Activas!$G$6:$G$25) -> 12 | J17: =_xlfn.XLOOKUP(B17,Activas!B:B,Activas!N:N) -> 35 | K17: =_xlfn.XLOOKUP(B17,Activas!B:B,Activas!P:P) -> 29 | L17: =H17+J17+K17 -> 1093 | M17: =INDEX([1]Base!$V:$V,MATCH(B17,[1]Base!$C:$C,0)) -> 1086 | N17: =IFERROR(L17/M17,"") -> 1.0064457 | O17: =V17-AB17 -> 208 | P17: =W17-AC17 -> 113 | Q17: =X17-AD17 -> 67 | R17: =Y17-AE17 -> 37 | S17: =Z17-AF17 -> 22 | T17: =AA17-AG17 -> 16 | V17: =INDEX([2]TD!C:C,MATCH($B17,[2]TD!$A:$A,0)) -> 723 | W17: =INDEX([2]TD!D:D,MATCH($B17,[2]TD!$A:$A,0)) -> 202 | X17: =INDEX([2]TD!E:E,MATCH($B17,[2]TD!$A:$A,0)) -> 104 | Y17: =INDEX([2]TD!F:F,MATCH($B17,[2]TD!$A:$A,0)) -> 55 | Z17: =INDEX([2]TD!G:G,MATCH($B17,[2]TD!$A:$A,0)) -> 29 | AA17: =INDEX([2]TD!H:H,MATCH($B17,[2]TD!$A:$A,0)) -> 20 | AB17: =ROUND(V17*AB$2,0)+AQ17 -> 515 | AC17: =ROUND(W17*AC$2,0)+AR17 -> 89 | AD17: =ROUND(X17*AD$2,0) -> 37 | AE17: =ROUND(Y17*AE$2,0)+AV17 -> 18 | AF17: =ROUND(Z17*AF$2,0)+AW17 -> 7 | AG17: =ROUND(AA17*AG$2,0) -> 4 | AH17: =SUM(AB17:AD17) -> 641 | AI17: =SUM(AB17:AG17)+J17 -> 705 | AJ17: =SUM(AE17:AG17) -> 29 | AM17: =_xlfn.XLOOKUP(B17,Activas!B:B,Activas!R:R) -> 705 | AN17: 29 | AO17: =O17/L17 -> 0.19030192 | AP17: =P17/L17 -> 0.10338518 | AQ17: =ROUND(AN17*50%,0) -> 15 | AR17: =AN17-AQ17 -> 14 | AS17: =AM17-AI17 -> 0 | AT17: =K17 -> 29 | AU17: -2 | AV17: =ROUND(AU17*50%,0) -> -1 | AW17: =AU17-AV17 -> -1 | AX17: =AT17-AJ17 -> 0 | BC17: =AB17/V17 -> 0.71230982 | BD17: =AC17/W17 -> 0.44059406 | BE17: =AD17/X17 -> 0.35576923 | BF17: =AE17/Y17 -> 0.32727273 | BG17: =AF17/Z17 -> 0.24137931 | BH17: =AG17/AA17 -> 0.2
B18: 700000428 | C18: Sector GALERÍA Yurieth | D18: Montería | E18: Yurieth Álvarez | F18: =VLOOKUP(B18,Activas!$B$5:$F$26,5,FALSE) -> 1683 | G18: =_xlfn.XLOOKUP(B18,Activas!B:B,Activas!M:M) -> 110 | H18: =F18-G18 -> 1573 | I18: =_xlfn.XLOOKUP(B18,Activas!$B$6:$B$25,Activas!$G$6:$G$25) -> 12 | J18: =_xlfn.XLOOKUP(B18,Activas!B:B,Activas!N:N) -> 80 | K18: =_xlfn.XLOOKUP(B18,Activas!B:B,Activas!P:P) -> 59 | L18: =H18+J18+K18 -> 1712 | M18: =INDEX([1]Base!$V:$V,MATCH(B18,[1]Base!$C:$C,0)) -> 1615 | N18: =IFERROR(L18/M18,"") -> 1.0600619 | O18: =V18-AB18 -> 348 | P18: =W18-AC18 -> 181 | Q18: =X18-AD18 -> 102 | R18: =Y18-AE18 -> 83 | S18: =Z18-AF18 -> 92 | T18: =AA18-AG18 -> 70 | V18: =INDEX([2]TD!C:C,MATCH($B18,[2]TD!$A:$A,0)) -> 1127 | W18: =INDEX([2]TD!D:D,MATCH($B18,[2]TD!$A:$A,0)) -> 289 | X18: =INDEX([2]TD!E:E,MATCH($B18,[2]TD!$A:$A,0)) -> 157 | Y18: =INDEX([2]TD!F:F,MATCH($B18,[2]TD!$A:$A,0)) -> 110 | Z18: =INDEX([2]TD!G:G,MATCH($B18,[2]TD!$A:$A,0)) -> 109 | AA18: =INDEX([2]TD!H:H,MATCH($B18,[2]TD!$A:$A,0)) -> 85 | AB18: =ROUND(V18*AB$2,0)+AQ18 -> 779 | AC18: =ROUND(W18*AC$2,0)+AR18 -> 108 | AD18: =ROUND(X18*AD$2,0) -> 55 | AE18: =ROUND(Y18*AE$2,0)+AV18 -> 27 | AF18: =ROUND(Z18*AF$2,0)+AW18 -> 17 | AG18: =ROUND(AA18*AG$2,0) -> 15 | AH18: =SUM(AB18:AD18) -> 942 | AI18: =SUM(AB18:AG18)+J18 -> 1081 | AJ18: =SUM(AE18:AG18) -> 59 | AM18: =_xlfn.XLOOKUP(B18,Activas!B:B,Activas!R:R) -> 1081 | AN18: 0 | AO18: =O18/L18 -> 0.20327103 | AP18: =P18/L18 -> 0.1057243 | AQ18: =ROUND(AN18*50%,0) -> 0 | AR18: =AN18-AQ18 -> 0 | AS18: =AM18-AI18 -> 0 | AT18: =K18 -> 59 | AU18: -23 | AV18: =ROUND(AU18*50%,0) -> -12 | AW18: =AU18-AV18 -> -11 | AX18: =AT18-AJ18 -> 0 | BC18: =AB18/V18 -> 0.69121562 | BD18: =AC18/W18 -> 0.37370242 | BE18: =AD18/X18 -> 0.35031847 | BF18: =AE18/Y18 -> 0.24545455 | BG18: =AF18/Z18 -> 0.1559633 | BH18: =AG18/AA18 -> 0.17647059
B19: 700000278 | C19: Sector CREACIÓN Perla | D19: Sucre_Magangue | E19: Perla Maria Sierra Diaz | F19: =VLOOKUP(B19,Activas!$B$5:$F$26,5,FALSE) -> 1261 | G19: =_xlfn.XLOOKUP(B19,Activas!B:B,Activas!M:M) -> 98 | H19: =F19-G19 -> 1163 | I19: =_xlfn.XLOOKUP(B19,Activas!$B$6:$B$25,Activas!$G$6:$G$25) -> 13 | J19: =_xlfn.XLOOKUP(B19,Activas!B:B,Activas!N:N) -> 52 | K19: =_xlfn.XLOOKUP(B19,Activas!B:B,Activas!P:P) -> 55 | L19: =H19+J19+K19 -> 1270 | M19: =INDEX([1]Base!$V:$V,MATCH(B19,[1]Base!$C:$C,0)) -> 1276 | N19: =IFERROR(L19/M19,"") -> 0.99529781 | O19: =V19-AB19 -> 234 | P19: =W19-AC19 -> 137 | Q19: =X19-AD19 -> 86 | R19: =Y19-AE19 -> 67 | S19: =Z19-AF19 -> 57 | T19: =AA19-AG19 -> 38 | V19: =INDEX([2]TD!C:C,MATCH($B19,[2]TD!$A:$A,0)) -> 795 | W19: =INDEX([2]TD!D:D,MATCH($B19,[2]TD!$A:$A,0)) -> 236 | X19: =INDEX([2]TD!E:E,MATCH($B19,[2]TD!$A:$A,0)) -> 132 | Y19: =INDEX([2]TD!F:F,MATCH($B19,[2]TD!$A:$A,0)) -> 98 | Z19: =INDEX([2]TD!G:G,MATCH($B19,[2]TD!$A:$A,0)) -> 73 | AA19: =INDEX([2]TD!H:H,MATCH($B19,[2]TD!$A:$A,0)) -> 46 | AB19: =ROUND(V19*AB$2,0)+AQ19 -> 561 | AC19: =ROUND(W19*AC$2,0)+AR19 -> 99 | AD19: =ROUND(X19*AD$2,0) -> 46 | AE19: =ROUND(Y19*AE$2,0)+AV19 -> 31 | AF19: =ROUND(Z19*AF$2,0)+AW19 -> 16 | AG19: =ROUND(AA19*AG$2,0) -> 8 | AH19: =SUM(AB19:AD19) -> 706 | AI19: =SUM(AB19:AG19)+J19 -> 813 | AJ19: =SUM(AE19:AG19) -> 55 | AM19: =_xlfn.XLOOKUP(B19,Activas!B:B,Activas!R:R) -> 813 | AN19: 22 | AO19: =O19/L19 -> 0.18425197 | AP19: =P19/L19 -> 0.10787402 | AQ19: =ROUND(AN19*50%,0) -> 11 | AR19: =AN19-AQ19 -> 11 | AS19: =AM19-AI19 -> 0 | AT19: =K19 -> 55 | AU19: -6 | AV19: =ROUND(AU19*50%,0) -> -3 | AW19: =AU19-AV19 -> -3 | AX19: =AT19-AJ19 -> 0 | BC19: =AB19/V19 -> 0.70566038 | BD19: =AC19/W19 -> 0.41949153 | BE19: =AD19/X19 -> 0.34848485 | BF19: =AE19/Y19 -> 0.31632653 | BG19: =AF19/Z19 -> 0.21917808 | BH19: =AG19/AA19 -> 0.17391304
B20: 700000178 | C20: Sector DESTELLO Karina | D20: Sucre_Sincelejo | E20: Karina Paola Vasquez Montalvo | F20: =VLOOKUP(B20,Activas!$B$5:$F$26,5,FALSE) -> 1669 | G20: =_xlfn.XLOOKUP(B20,Activas!B:B,Activas!M:M) -> 102 | H20: =F20-G20 -> 1567 | I20: =_xlfn.XLOOKUP(B20,Activas!$B$6:$B$25,Activas!$G$6:$G$25) -> 13 | J20: =_xlfn.XLOOKUP(B20,Activas!B:B,Activas!N:N) -> 88 | K20: =_xlfn.XLOOKUP(B20,Activas!B:B,Activas!P:P) -> 63 | L20: =H20+J20+K20 -> 1718 | M20: =INDEX([1]Base!$V:$V,MATCH(B20,[1]Base!$C:$C,0)) -> 1704 | N20: =IFERROR(L20/M20,"") -> 1.008216 | O20: =V20-AB20 -> 345 | P20: =W20-AC20 -> 179 | Q20: =X20-AD20 -> 115 | R20: =Y20-AE20 -> 76 | S20: =Z20-AF20 -> 90 | T20: =AA20-AG20 -> 76 | V20: =INDEX([2]TD!C:C,MATCH($B20,[2]TD!$A:$A,0)) -> 1108 | W20: =INDEX([2]TD!D:D,MATCH($B20,[2]TD!$A:$A,0)) -> 281 | X20: =INDEX([2]TD!E:E,MATCH($B20,[2]TD!$A:$A,0)) -> 178 | Y20: =INDEX([2]TD!F:F,MATCH($B20,[2]TD!$A:$A,0)) -> 102 | Z20: =INDEX([2]TD!G:G,MATCH($B20,[2]TD!$A:$A,0)) -> 110 | AA20: =INDEX([2]TD!H:H,MATCH($B20,[2]TD!$A:$A,0)) -> 93 | AB20: =ROUND(V20*AB$2,0)+AQ20 -> 763 | AC20: =ROUND(W20*AC$2,0)+AR20 -> 102 | AD20: =ROUND(X20*AD$2,0) -> 63 | AE20: =ROUND(Y20*AE$2,0)+AV20 -> 26 | AF20: =ROUND(Z20*AF$2,0)+AW20 -> 20 | AG20: =ROUND(AA20*AG$2,0) -> 17 | AH20: =SUM(AB20:AD20) -> 928 | AI20: =SUM(AB20:AG20)+J20 -> 1079 | AJ20: =SUM(AE20:AG20) -> 63 | AM20: =_xlfn.XLOOKUP(B20,Activas!B:B,Activas!R:R) -> 1079 | AN20: -6 | AO20: =O20/L20 -> 0.2008149 | AP20: =P20/L20 -> 0.10419092 | AQ20: =ROUND(AN20*50%,0) -> -3 | AR20: =AN20-AQ20 -> -3 | AS20: =AM20-AI20 -> 0 | AT20: =K20 -> 63 | AU20: -19 | AV20: =ROUND(AU20*50%,0) -> -10 | AW20: =AU20-AV20 -> -9 | AX20: =AT20-AJ20 -> 0 | BC20: =AB20/V20 -> 0.68862816 | BD20: =AC20/W20 -> 0.36298932 | BE20: =AD20/X20 -> 0.35393258 | BF20: =AE20/Y20 -> 0.25490196 | BG20: =AF20/Z20 -> 0.18181818 | BH20: =AG20/AA20 -> 0.1827957
B21: 700000423 | C21: Sector ARMONÍA Claudia | D21: Sucre_Sincelejo | E21: Claudia Patricia Benitez | F21: =VLOOKUP(B21,Activas!$B$5:$F$26,5,FALSE) -> 1699 | G21: =_xlfn.XLOOKUP(B21,Activas!B:B,Activas!M:M) -> 105 | H21: =F21-G21 -> 1594 | I21: =_xlfn.XLOOKUP(B21,Activas!$B$6:$B$25,Activas!$G$6:$G$25) -> 13 | J21: =_xlfn.XLOOKUP(B21,Activas!B:B,Activas!N:N) -> 80 | K21: =_xlfn.XLOOKUP(B21,Activas!B:B,Activas!P:P) -> 70 | L21: =H21+J21+K21 -> 1744 | M21: =INDEX([1]Base!$V:$V,MATCH(B21,[1]Base!$C:$C,0)) -> 1647 | N21: =IFERROR(L21/M21,"") -> 1.058895 | O21: =V21-AB21 -> 337 | P21: =W21-AC21 -> 214 | Q21: =X21-AD21 -> 110 | R21: =Y21-AE21 -> 73 | S21: =Z21-AF21 -> 78 | T21: =AA21-AG21 -> 74 | V21: =INDEX([2]TD!C:C,MATCH($B21,[2]TD!$A:$A,0)) -> 1085 | W21: =INDEX([2]TD!D:D,MATCH($B21,[2]TD!$A:$A,0)) -> 339 | X21: =INDEX([2]TD!E:E,MATCH($B21,[2]TD!$A:$A,0)) -> 170 | Y21: =INDEX([2]TD!F:F,MATCH($B21,[2]TD!$A:$A,0)) -> 105 | Z21: =INDEX([2]TD!G:G,MATCH($B21,[2]TD!$A:$A,0)) -> 100 | AA21: =INDEX([2]TD!H:H,MATCH($B21,[2]TD!$A:$A,0)) -> 90 | AB21: =ROUND(V21*AB$2,0)+AQ21 -> 748 | AC21: =ROUND(W21*AC$2,0)+AR21 -> 125 | AD21: =ROUND(X21*AD$2,0) -> 60 | AE21: =ROUND(Y21*AE$2,0)+AV21 -> 32 | AF21: =ROUND(Z21*AF$2,0)+AW21 -> 22 | AG21: =ROUND(AA21*AG$2,0) -> 16 | AH21: =SUM(AB21:AD21) -> 933 | AI21: =SUM(AB21:AG21)+J21 -> 1083 | AJ21: =SUM(AE21:AG21) -> 70 | AM21: =_xlfn.XLOOKUP(B21,Activas!B:B,Activas!R:R) -> 1083 | AN21: -4 | AO21: =O21/L21 -> 0.19323394 | AP21: =P21/L21 -> 0.12270642 | AQ21: =ROUND(AN21*50%,0) -> -2 | AR21: =AN21-AQ21 -> -2 | AS21: =AM21-AI21 -> 0 | AT21: =K21 -> 70 | AU21: -9 | AV21: =ROUND(AU21*50%,0) -> -5 | AW21: =AU21-AV21 -> -4 | AX21: =AT21-AJ21 -> 0 | BC21: =AB21/V21 -> 0.68940092 | BD21: =AC21/W21 -> 0.36873156 | BE21: =AD21/X21 -> 0.35294118 | BF21: =AE21/Y21 -> 0.3047619 | BG21: =AF21/Z21 -> 0.22 | BH21: =AG21/AA21 -> 0.17777778
B22: 700000232 | C22: Sector EXPRESIÓN Nayibe | D22: Poblaciones Cundinamarca_Facatativá/Madrid | E22: Nayibe Esmeralda Pulido | F22: =VLOOKUP(B22,Activas!$B$5:$F$26,5,FALSE) -> 1255 | G22: =_xlfn.XLOOKUP(B22,Activas!B:B,Activas!M:M) -> 81 | H22: =F22-G22 -> 1174 | I22: =_xlfn.XLOOKUP(B22,Activas!$B$6:$B$25,Activas!$G$6:$G$25) -> 13 | J22: =_xlfn.XLOOKUP(B22,Activas!B:B,Activas!N:N) -> 48 | K22: =_xlfn.XLOOKUP(B22,Activas!B:B,Activas!P:P) -> 52 | L22: =H22+J22+K22 -> 1274 | M22: =INDEX([1]Base!$V:$V,MATCH(B22,[1]Base!$C:$C,0)) -> 1309 | N22: =IFERROR(L22/M22,"") -> 0.97326203 | O22: =V22-AB22 -> 234 | P22: =W22-AC22 -> 150 | Q22: =X22-AD22 -> 102 | R22: =Y22-AE22 -> 55 | S22: =Z22-AF22 -> 50 | T22: =AA22-AG22 -> 46 | V22: =INDEX([2]TD!C:C,MATCH($B22,[2]TD!$A:$A,0)) -> 772 | W22: =INDEX([2]TD!D:D,MATCH($B22,[2]TD!$A:$A,0)) -> 245 | X22: =INDEX([2]TD!E:E,MATCH($B22,[2]TD!$A:$A,0)) -> 158 | Y22: =INDEX([2]TD!F:F,MATCH($B22,[2]TD!$A:$A,0)) -> 81 | Z22: =INDEX([2]TD!G:G,MATCH($B22,[2]TD!$A:$A,0)) -> 66 | AA22: =INDEX([2]TD!H:H,MATCH($B22,[2]TD!$A:$A,0)) -> 56 | AB22: =ROUND(V22*AB$2,0)+AQ22 -> 538 | AC22: =ROUND(W22*AC$2,0)+AR22 -> 95 | AD22: =ROUND(X22*AD$2,0) -> 56 | AE22: =ROUND(Y22*AE$2,0)+AV22 -> 26 | AF22: =ROUND(Z22*AF$2,0)+AW22 -> 16 | AG22: =ROUND(AA22*AG$2,0) -> 10 | AH22: =SUM(AB22:AD22) -> 689 | AI22: =SUM(AB22:AG22)+J22 -> 789 | AJ22: =SUM(AE22:AG22) -> 52 | AM22: =_xlfn.XLOOKUP(B22,Activas!B:B,Activas!R:R) -> 789 | AN22: 8 | AO22: =O22/L22 -> 0.18367347 | AP22: =P22/L22 -> 0.1177394 | AQ22: =ROUND(AN22*50%,0) -> 4 | AR22: =AN22-AQ22 -> 4 | AS22: =AM22-AI22 -> 0 | AT22: =K22 -> 52 | AU22: -3 | AV22: =ROUND(AU22*50%,0) -> -2 | AW22: =AU22-AV22 -> -1 | AX22: =AT22-AJ22 -> 0 | BC22: =AB22/V22 -> 0.69689119 | BD22: =AC22/W22 -> 0.3877551 | BE22: =AD22/X22 -> 0.35443038 | BF22: =AE22/Y22 -> 0.32098765 | BG22: =AF22/Z22 -> 0.24242424 | BH22: =AG22/AA22 -> 0.17857143
B23: 700000459 | C23: Sector MATICES Clery | D23: Poblaciones Cundinamarca_Facatativá/Madrid | E23: Clery Enith Cuellar Rojas | F23: =VLOOKUP(B23,Activas!$B$5:$F$26,5,FALSE) -> 1233 | G23: =_xlfn.XLOOKUP(B23,Activas!B:B,Activas!M:M) -> 78 | H23: =F23-G23 -> 1155 | I23: =_xlfn.XLOOKUP(B23,Activas!$B$6:$B$25,Activas!$G$6:$G$25) -> 13 | J23: =_xlfn.XLOOKUP(B23,Activas!B:B,Activas!N:N) -> 58 | K23: =_xlfn.XLOOKUP(B23,Activas!B:B,Activas!P:P) -> 47 | L23: =H23+J23+K23 -> 1260 | M23: =INDEX([1]Base!$V:$V,MATCH(B23,[1]Base!$C:$C,0)) -> 1187 | N23: =IFERROR(L23/M23,"") -> 1.0614996 | O23: =V23-AB23 -> 254 | P23: =W23-AC23 -> 158 | Q23: =X23-AD23 -> 79 | R23: =Y23-AE23 -> 54 | S23: =Z23-AF23 -> 46 | T23: =AA23-AG23 -> 42 | V23: =INDEX([2]TD!C:C,MATCH($B23,[2]TD!$A:$A,0)) -> 795 | W23: =INDEX([2]TD!D:D,MATCH($B23,[2]TD!$A:$A,0)) -> 237 | X23: =INDEX([2]TD!E:E,MATCH($B23,[2]TD!$A:$A,0)) -> 122 | Y23: =INDEX([2]TD!F:F,MATCH($B23,[2]TD!$A:$A,0)) -> 78 | Z23: =INDEX([2]TD!G:G,MATCH($B23,[2]TD!$A:$A,0)) -> 60 | AA23: =INDEX([2]TD!H:H,MATCH($B23,[2]TD!$A:$A,0)) -> 51 | AB23: =ROUND(V23*AB$2,0)+AQ23 -> 541 | AC23: =ROUND(W23*AC$2,0)+AR23 -> 79 | AD23: =ROUND(X23*AD$2,0) -> 43 | AE23: =ROUND(Y23*AE$2,0)+AV23 -> 24 | AF23: =ROUND(Z23*AF$2,0)+AW23 -> 14 | AG23: =ROUND(AA23*AG$2,0) -> 9 | AH23: =SUM(AB23:AD23) -> 663 | AI23: =SUM(AB23:AG23)+J23 -> 768 | AJ23: =SUM(AE23:AG23) -> 47 | AM23: =_xlfn.XLOOKUP(B23,Activas!B:B,Activas!R:R) -> 768 | AN23: -18 | AO23: =O23/L23 -> 0.2015873 | AP23: =P23/L23 -> 0.12539683 | AQ23: =ROUND(AN23*50%,0) -> -9 | AR23: =AN23-AQ23 -> -9 | AS23: =AM23-AI23 -> 0 | AT23: =K23 -> 47 | AU23: -5 | AV23: =ROUND(AU23*50%,0) -> -3 | AW23: =AU23-AV23 -> -2 | AX23: =AT23-AJ23 -> 0 | BC23: =AB23/V23 -> 0.68050314 | BD23: =AC23/W23 -> 0.33333333 | BE23: =AD23/X23 -> 0.35245902 | BF23: =AE23/Y23 -> 0.30769231 | BG23: =AF23/Z23 -> 0.23333333 | BH23: =AG23/AA23 -> 0.17647059
... B26: 700000458 | C26: Sector LIENZO Ángela | D26: Poblaciones Cundinamarca_Chía | E26: Ángela Rios | F26: =VLOOKUP(B26,Activas!$B$5:$F$26,5,FALSE) -> 1439 | G26: =_xlfn.XLOOKUP(B26,Activas!B:B,Activas!M:M) -> 78 | H26: =F26-G26 -> 1361 | I26: =_xlfn.XLOOKUP(B26,Activas!$B$6:$B$25,Activas!$G$6:$G$25) -> 13 | J26: =_xlfn.XLOOKUP(B26,Activas!B:B,Activas!N:N) -> 48 | K26: =_xlfn.XLOOKUP(B26,Activas!B:B,Activas!P:P) -> 55 | L26: =H26+J26+K26 -> 1464 | M26: =INDEX([1]Base!$V:$V,MATCH(B26,[1]Base!$C:$C,0)) -> 1427 | N26: =IFERROR(L26/M26,"") -> 1.0259285 | O26: =V26-AB26 -> 292 | P26: =W26-AC26 -> 182 | Q26: =X26-AD26 -> 87 | R26: =Y26-AE26 -> 51 | S26: =Z26-AF26 -> 56 | T26: =AA26-AG26 -> 36 | V26: =INDEX([2]TD!C:C,MATCH($B26,[2]TD!$A:$A,0)) -> 939 | W26: =INDEX([2]TD!D:D,MATCH($B26,[2]TD!$A:$A,0)) -> 287 | X26: =INDEX([2]TD!E:E,MATCH($B26,[2]TD!$A:$A,0)) -> 135 | Y26: =INDEX([2]TD!F:F,MATCH($B26,[2]TD!$A:$A,0)) -> 78 | Z26: =INDEX([2]TD!G:G,MATCH($B26,[2]TD!$A:$A,0)) -> 76 | AA26: =INDEX([2]TD!H:H,MATCH($B26,[2]TD!$A:$A,0)) -> 44 | AB26: =ROUND(V26*AB$2,0)+AQ26 -> 647 | AC26: =ROUND(W26*AC$2,0)+AR26 -> 105 | AD26: =ROUND(X26*AD$2,0) -> 48 | AE26: =ROUND(Y26*AE$2,0)+AV26 -> 27 | AF26: =ROUND(Z26*AF$2,0)+AW26 -> 20 | AG26: =ROUND(AA26*AG$2,0) -> 8 | AH26: =SUM(AB26:AD26) -> 800 | AI26: =SUM(AB26:AG26)+J26 -> 903 | AJ26: =SUM(AE26:AG26) -> 55 | AM26: =_xlfn.XLOOKUP(B26,Activas!B:B,Activas!R:R) -> 903 | AN26: -4 | AO26: =O26/L26 -> 0.19945355 | AP26: =P26/L26 -> 0.12431694 | AQ26: =ROUND(AN26*50%,0) -> -2 | AR26: =AN26-AQ26 -> -2 | AS26: =AM26-AI26 -> 0 | AT26: =K26 -> 55 | AU26: 0 | AV26: =ROUND(AU26*50%,0) -> 0 | AW26: =AU26-AV26 -> 0 | AX26: =AT26-AJ26 -> 0 | BC26: =AB26/V26 -> 0.68903088 | BD26: =AC26/W26 -> 0.36585366 | BE26: =AD26/X26 -> 0.35555556 | BF26: =AE26/Y26 -> 0.34615385 | BG26: =AF26/Z26 -> 0.26315789 | BH26: =AG26/AA26 -> 0.18181818
F31: 1 | G31: =F31+1 -> 2 | H31: =G31+1 -> 3 | I31: =H31+1 -> 4 | J31: =I31+1 -> 5 | K31: =J31+1 -> 6 | L31: =K31+1 -> 7 | M31: =L31+1 -> 8 | N31: =M31+1 -> 9 | ... AX31: =AW31+1 -> 45

Sheet Historicos Inicios 
A1: Cod. Sector | B1: Sector | C1: Clúster | D1: 202501 | E1: 202502 | F1: 202503 | G1: 202504 | H1: 202505 | I1: 202506 | J1: =I1+1 -> 202507 | K1: =J1+1 -> 202508 | L1: =K1+1 -> 202509 | M1: =L1+1 -> 202510 | N1: =M1+1 -> 202511 | O1: =N1+1 -> 202512 | P1: =O1+1 -> 202513 | Q1: =P1+1 -> 202514 | ... T1: =S1+1 -> 202517 | U1: 202601 | V1: =U1+1 -> 202602 | W1: =V1+1 -> 202603 | X1: =W1+1 -> 202604 | Y1: =X1+1 -> 202605 | Z1: =Y1+1 -> 202606 | AA1: =Z1+1 -> 202607 | AB1: =AA1+1 -> 202608 | AC1: =AB1+1 -> 202609 | ... AE1: =AD1+1 -> 202611 | AF1: PROMEDIO | AG1: Meta | AI1: Cod. Sector | AJ1: Sector | AK1: %Cump Disp C11 | AL1: Exigencia | AN1: Desde | AO1: Hasta | AP1: Exigencia
A2: 700000021 | B2: Sector COLORES Karen | C2: Bogotá_Norte-Centro | D2: 19 | E2: 22 | F2: 51 | G2: 49 | H2: 52 | I2: 63 | J2: 44 | K2: 37 | L2: 37 | M2: 77 | N2: 33 | O2: 40 | P2: 54 | Q2: =VLOOKUP(A2,[3]CUBO!$C:$DY,127,FALSE) -> 41 | R2: =VLOOKUP(A2,[4]CUBO!$C:$DY,127,FALSE) -> 33 | S2: =VLOOKUP(A2,[5]CUBO!$C:$DY,127,FALSE) -> 28 | T2: =VLOOKUP(A2,[6]CUBO!$C:$DY,127,FALSE) -> 44 | U2: =VLOOKUP(A2,[7]CUBO!$C:$DY,127,FALSE) -> 32 | V2: =VLOOKUP(A2,[8]CUBO!$C:$DY,127,FALSE) -> 38 | W2: =VLOOKUP(A2,[9]CUBO!$C:$DY,127,FALSE) -> 47 | X2: =VLOOKUP(A2,[10]CUBO!$C:$DY,127,FALSE) -> 41 | Y2: =VLOOKUP(A2,[11]CUBO!$C:$DY,127,FALSE) -> 78 | Z2: =VLOOKUP(A2,[12]CUBO!$C:$DY,127,FALSE) -> 66 | AA2: =_xlfn.XLOOKUP(A2,[13]CUBO!$B:$B,[13]CUBO!$DX:$DX) -> 61 | AB2: 55 | AC2: 56 | AD2: 46 | AE2: 41 | AF2: =ROUND(AVERAGE(U2:AE2),0) -> 51 | AG2: =VLOOKUP(A2,$AI$2:$AL$21,4,FALSE)+AF2 -> 54 | AI2: 700000459 | AJ2: Sector MATICES Clery | AK2: =_xlfn.XLOOKUP(AI2,'Histórico Actividad'!B:B,'Histórico Actividad'!P:P) -> 1.1261426 | AL2: =VLOOKUP(AK2,$AN$1:$AP$5,3,TRUE) -> 0 | AN2: 0 | AO2: 0.9499 | AP2: 5
A3: 700000455 | B3: Sector ESPLENDOR Carolina | C3: Bogotá_Norte-Centro | D3: 29 | E3: 66 | F3: 55 | G3: 84 | H3: 64 | I3: 82 | J3: 82 | K3: 68 | L3: 71 | M3: 118 | N3: 101 | O3: 97 | P3: 76 | Q3: =VLOOKUP(A3,[3]CUBO!$C:$DY,127,FALSE) -> 92 | R3: =VLOOKUP(A3,[4]CUBO!$C:$DY,127,FALSE) -> 73 | S3: =VLOOKUP(A3,[5]CUBO!$C:$DY,127,FALSE) -> 104 | T3: =VLOOKUP(A3,[6]CUBO!$C:$DY,127,FALSE) -> 76 | U3: =VLOOKUP(A3,[7]CUBO!$C:$DY,127,FALSE) -> 71 | V3: =VLOOKUP(A3,[8]CUBO!$C:$DY,127,FALSE) -> 65 | W3: =VLOOKUP(A3,[9]CUBO!$C:$DY,127,FALSE) -> 84 | X3: =VLOOKUP(A3,[10]CUBO!$C:$DY,127,FALSE) -> 68 | Y3: =VLOOKUP(A3,[11]CUBO!$C:$DY,127,FALSE) -> 71 | Z3: =VLOOKUP(A3,[12]CUBO!$C:$DY,127,FALSE) -> 64 | AA3: =_xlfn.XLOOKUP(A3,[13]CUBO!$B:$B,[13]CUBO!$DX:$DX) -> 55 | AB3: 47 | AC3: 52 | AD3: 45 | AE3: 57 | AF3: =ROUND(AVERAGE(U3:AE3),0) -> 62 | AG3: =VLOOKUP(A3,$AI$2:$AL$21,4,FALSE)+AF3 -> 65 | AI3: 700000423 | AJ3: Sector ARMONÍA Claudia | AK3: =_xlfn.XLOOKUP(AI3,'Histórico Actividad'!B:B,'Histórico Actividad'!P:P) -> 1.0397797 | AL3: =VLOOKUP(AK3,$AN$1:$AP$5,3,TRUE) -> 3 | AN3: 0.95 | AO3: 0.9999 | AP3: 4
A4: 700000457 | B4: Sector PINCEL Iliana | C4: Bogotá_Norte-Centro | D4: 23 | E4: 32 | F4: 40 | G4: 55 | H4: 33 | I4: 44 | J4: 32 | K4: 24 | L4: 29 | M4: 62 | N4: 39 | O4: 24 | P4: 31 | Q4: =VLOOKUP(A4,[3]CUBO!$C:$DY,127,FALSE) -> 40 | R4: =VLOOKUP(A4,[4]CUBO!$C:$DY,127,FALSE) -> 40 | S4: =VLOOKUP(A4,[5]CUBO!$C:$DY,127,FALSE) -> 51 | T4: =VLOOKUP(A4,[6]CUBO!$C:$DY,127,FALSE) -> 39 | U4: =VLOOKUP(A4,[7]CUBO!$C:$DY,127,FALSE) -> 27 | V4: =VLOOKUP(A4,[8]CUBO!$C:$DY,127,FALSE) -> 42 | W4: =VLOOKUP(A4,[9]CUBO!$C:$DY,127,FALSE) -> 59 | X4: =VLOOKUP(A4,[10]CUBO!$C:$DY,127,FALSE) -> 48 | Y4: =VLOOKUP(A4,[11]CUBO!$C:$DY,127,FALSE) -> 49 | Z4: =VLOOKUP(A4,[12]CUBO!$C:$DY,127,FALSE) -> 37 | AA4: =_xlfn.XLOOKUP(A4,[13]CUBO!$B:$B,[13]CUBO!$DX:$DX) -> 40 | AB4: 48 | AC4: 48 | AD4: 47 | AE4: 50 | AF4: =ROUND(AVERAGE(U4:AE4),0) -> 45 | AG4: =VLOOKUP(A4,$AI$2:$AL$21,4,FALSE)+AF4 -> 49 | AI4: 700000428 | AJ4: Sector GALERÍA Yurieth | AK4: =_xlfn.XLOOKUP(AI4,'Histórico Actividad'!B:B,'Histórico Actividad'!P:P) -> 1.0651899 | AL4: =VLOOKUP(AK4,$AN$1:$AP$5,3,TRUE) -> 0 | AN4: 1 | AO4: 1.0499 | AP4: 3
A5: 700000281 | B5: Sector PICASSO Regina | C5: Poblaciones córdoba_Lórica | D5: 62 | E5: 86 | F5: 49 | G5: 57 | H5: 46 | I5: 40 | J5: 58 | K5: 51 | L5: 48 | M5: 97 | N5: 45 | O5: 52 | P5: 47 | Q5: =VLOOKUP(A5,[3]CUBO!$C:$DY,127,FALSE) -> 43 | R5: =VLOOKUP(A5,[4]CUBO!$C:$DY,127,FALSE) -> 44 | S5: =VLOOKUP(A5,[5]CUBO!$C:$DY,127,FALSE) -> 33 | T5: =VLOOKUP(A5,[6]CUBO!$C:$DY,127,FALSE) -> 32 | U5: =VLOOKUP(A5,[7]CUBO!$C:$DY,127,FALSE) -> 54 | V5: =VLOOKUP(A5,[8]CUBO!$C:$DY,127,FALSE) -> 50 | W5: =VLOOKUP(A5,[9]CUBO!$C:$DY,127,FALSE) -> 48 | X5: =VLOOKUP(A5,[10]CUBO!$C:$DY,127,FALSE) -> 67 | Y5: =VLOOKUP(A5,[11]CUBO!$C:$DY,127,FALSE) -> 69 | Z5: =VLOOKUP(A5,[12]CUBO!$C:$DY,127,FALSE) -> 57 | AA5: =_xlfn.XLOOKUP(A5,[13]CUBO!$B:$B,[13]CUBO!$DX:$DX) -> 57 | AB5: 61 | AC5: 71 | AD5: 62 | AE5: 46 | AF5: =ROUND(AVERAGE(U5:AE5),0) -> 58 | AG5: =VLOOKUP(A5,$AI$2:$AL$21,4,FALSE)+AF5 -> 61 | AI5: 700000281 | AJ5: Sector PICASSO Regina | AK5: =_xlfn.XLOOKUP(AI5,'Histórico Actividad'!B:B,'Histórico Actividad'!P:P) -> 1.0400572 | AL5: =VLOOKUP(AK5,$AN$1:$AP$5,3,TRUE) -> 3 | AN5: 1.05 | AO5: 1.075 | AP5: 0
A6: 700000254 | B6: Sector CREATIVIDAD Yomaira | C6: Poblaciones córdoba_Tierralta | D6: 24 | E6: 49 | F6: 58 | G6: 54 | H6: 44 | I6: 43 | J6: 40 | K6: 42 | L6: 46 | M6: 75 | N6: 47 | O6: 49 | P6: 50 | Q6: =VLOOKUP(A6,[3]CUBO!$C:$DY,127,FALSE) -> 60 | R6: =VLOOKUP(A6,[4]CUBO!$C:$DY,127,FALSE) -> 65 | S6: =VLOOKUP(A6,[5]CUBO!$C:$DY,127,FALSE) -> 55 | T6: =VLOOKUP(A6,[6]CUBO!$C:$DY,127,FALSE) -> 52 | U6: =VLOOKUP(A6,[7]CUBO!$C:$DY,127,FALSE) -> 35 | V6: =VLOOKUP(A6,[8]CUBO!$C:$DY,127,FALSE) -> 60 | W6: =VLOOKUP(A6,[9]CUBO!$C:$DY,127,FALSE) -> 44 | X6: =VLOOKUP(A6,[10]CUBO!$C:$DY,127,FALSE) -> 45 | Y6: =VLOOKUP(A6,[11]CUBO!$C:$DY,127,FALSE) -> 55 | Z6: =VLOOKUP(A6,[12]CUBO!$C:$DY,127,FALSE) -> 46 | AA6: =_xlfn.XLOOKUP(A6,[13]CUBO!$B:$B,[13]CUBO!$DX:$DX) -> 37 | AB6: 44 | AC6: 52 | AD6: 18 | AE6: 52 | AF6: =ROUND(AVERAGE(U6:AE6),0) -> 44 | AG6: =VLOOKUP(A6,$AI$2:$AL$21,4,FALSE)+AF6 -> 49 | AI6: 700000278 | AJ6: Sector CREACIÓN Perla | AK6: =_xlfn.XLOOKUP(AI6,'Histórico Actividad'!B:B,'Histórico Actividad'!P:P) -> 0.99841647 | AL6: =VLOOKUP(AK6,$AN$1:$AP$5,3,TRUE) -> 4
A7: 700000098 | B7: Sector MOSAICO Julieth | C7: Montería | D7: 10 | E7: 28 | F7: 21 | G7: 26 | H7: 32 | I7: 41 | J7: 36 | K7: 18 | L7: 21 | M7: 50 | N7: 26 | O7: 23 | P7: 30 | Q7: =VLOOKUP(A7,[3]CUBO!$C:$DY,127,FALSE) -> 30 | R7: =VLOOKUP(A7,[4]CUBO!$C:$DY,127,FALSE) -> 38 | S7: =VLOOKUP(A7,[5]CUBO!$C:$DY,127,FALSE) -> 28 | T7: =VLOOKUP(A7,[6]CUBO!$C:$DY,127,FALSE) -> 23 | U7: =VLOOKUP(A7,[7]CUBO!$C:$DY,127,FALSE) -> 33 | V7: =VLOOKUP(A7,[8]CUBO!$C:$DY,127,FALSE) -> 44 | W7: =VLOOKUP(A7,[9]CUBO!$C:$DY,127,FALSE) -> 24 | X7: =VLOOKUP(A7,[10]CUBO!$C:$DY,127,FALSE) -> 31 | Y7: =VLOOKUP(A7,[11]CUBO!$C:$DY,127,FALSE) -> 59 | Z7: =VLOOKUP(A7,[12]CUBO!$C:$DY,127,FALSE) -> 57 | AA7: =_xlfn.XLOOKUP(A7,[13]CUBO!$B:$B,[13]CUBO!$DX:$DX) -> 42 | AB7: 43 | AC7: 50 | AD7: 43 | AE7: 51 | AF7: =ROUND(AVERAGE(U7:AE7),0) -> 43 | AG7: =VLOOKUP(A7,$AI$2:$AL$21,4,FALSE)+AF7 -> 46 | AI7: 700000021 | AJ7: Sector COLORES Karen | AK7: =_xlfn.XLOOKUP(AI7,'Histórico Actividad'!B:B,'Histórico Actividad'!P:P) -> 1.0023878 | AL7: =VLOOKUP(AK7,$AN$1:$AP$5,3,TRUE) -> 3
A8: 700000133 | B8: Sector INSPIRACIÓN Vanesa | C8: Montería | D8: 35 | E8: 59 | F8: 49 | G8: 36 | H8: 30 | I8: 32 | J8: 52 | K8: 38 | L8: 37 | M8: 69 | N8: 34 | O8: 47 | P8: 28 | Q8: =VLOOKUP(A8,[3]CUBO!$C:$DY,127,FALSE) -> 32 | R8: =VLOOKUP(A8,[4]CUBO!$C:$DY,127,FALSE) -> 28 | S8: =VLOOKUP(A8,[5]CUBO!$C:$DY,127,FALSE) -> 26 | T8: =VLOOKUP(A8,[6]CUBO!$C:$DY,127,FALSE) -> 17 | U8: =VLOOKUP(A8,[7]CUBO!$C:$DY,127,FALSE) -> 21 | V8: =VLOOKUP(A8,[8]CUBO!$C:$DY,127,FALSE) -> 36 | W8: =VLOOKUP(A8,[9]CUBO!$C:$DY,127,FALSE) -> 26 | X8: =VLOOKUP(A8,[10]CUBO!$C:$DY,127,FALSE) -> 29 | Y8: =VLOOKUP(A8,[11]CUBO!$C:$DY,127,FALSE) -> 39 | Z8: =VLOOKUP(A8,[12]CUBO!$C:$DY,127,FALSE) -> 37 | AA8: =_xlfn.XLOOKUP(A8,[13]CUBO!$B:$B,[13]CUBO!$DX:$DX) -> 40 | AB8: 29 | AC8: 31 | AD8: 29 | AE8: 37 | AF8: =ROUND(AVERAGE(U8:AE8),0) -> 32 | AG8: =VLOOKUP(A8,$AI$2:$AL$21,4,FALSE)+AF8 -> 35 | AI8: 700000466 | AJ8: Sector EMOCIONES Dolly | AK8: =_xlfn.XLOOKUP(AI8,'Histórico Actividad'!B:B,'Histórico Actividad'!P:P) -> 1.0123796 | AL8: =VLOOKUP(AK8,$AN$1:$AP$5,3,TRUE) -> 3
A9: 700000428 | B9: Sector GALERÍA Yurieth | C9: Montería | D9: 54 | E9: 93 | F9: 84 | G9: 88 | H9: 73 | I9: 60 | J9: 77 | K9: 53 | L9: 63 | M9: 113 | N9: 64 | O9: 51 | P9: 58 | Q9: =VLOOKUP(A9,[3]CUBO!$C:$DY,127,FALSE) -> 71 | R9: =VLOOKUP(A9,[4]CUBO!$C:$DY,127,FALSE) -> 63 | S9: =VLOOKUP(A9,[5]CUBO!$C:$DY,127,FALSE) -> 68 | T9: =VLOOKUP(A9,[6]CUBO!$C:$DY,127,FALSE) -> 44 | U9: =VLOOKUP(A9,[7]CUBO!$C:$DY,127,FALSE) -> 47 | V9: =VLOOKUP(A9,[8]CUBO!$C:$DY,127,FALSE) -> 104 | W9: =VLOOKUP(A9,[9]CUBO!$C:$DY,127,FALSE) -> 65 | X9: =VLOOKUP(A9,[10]CUBO!$C:$DY,127,FALSE) -> 92 | Y9: =VLOOKUP(A9,[11]CUBO!$C:$DY,127,FALSE) -> 92 | Z9: =VLOOKUP(A9,[12]CUBO!$C:$DY,127,FALSE) -> 66 | AA9: =_xlfn.XLOOKUP(A9,[13]CUBO!$B:$B,[13]CUBO!$DX:$DX) -> 76 | AB9: 79 | AC9: 80 | AD9: 76 | AE9: 101 | AF9: =ROUND(AVERAGE(U9:AE9),0) -> 80 | AG9: =VLOOKUP(A9,$AI$2:$AL$21,4,FALSE)+AF9 -> 80 | AI9: 700000098 | AJ9: Sector MOSAICO Julieth | AK9: =_xlfn.XLOOKUP(AI9,'Histórico Actividad'!B:B,'Histórico Actividad'!P:P) -> 1.0475352 | AL9: =VLOOKUP(AK9,$AN$1:$AP$5,3,TRUE) -> 3
A10: 700000278 | B10: Sector CREACIÓN Perla | C10: Sucre_Magangue | D10: 56 | E10: 57 | F10: 56 | G10: 76 | H10: 53 | I10: 50 | J10: 44 | K10: 54 | L10: 45 | M10: 86 | N10: 80 | O10: 76 | P10: 73 | Q10: =VLOOKUP(A10,[3]CUBO!$C:$DY,127,FALSE) -> 66 | R10: =VLOOKUP(A10,[4]CUBO!$C:$DY,127,FALSE) -> 62 | S10: =VLOOKUP(A10,[5]CUBO!$C:$DY,127,FALSE) -> 42 | T10: =VLOOKUP(A10,[6]CUBO!$C:$DY,127,FALSE) -> 47 | U10: =VLOOKUP(A10,[7]CUBO!$C:$DY,127,FALSE) -> 22 | V10: =VLOOKUP(A10,[8]CUBO!$C:$DY,127,FALSE) -> 44 | W10: =VLOOKUP(A10,[9]CUBO!$C:$DY,127,FALSE) -> 62 | X10: =VLOOKUP(A10,[10]CUBO!$C:$DY,127,FALSE) -> 62 | Y10: =VLOOKUP(A10,[11]CUBO!$C:$DY,127,FALSE) -> 67 | Z10: =VLOOKUP(A10,[12]CUBO!$C:$DY,127,FALSE) -> 47 | AA10: =_xlfn.XLOOKUP(A10,[13]CUBO!$B:$B,[13]CUBO!$DX:$DX) -> 49 | AB10: 45 | AC10: 46 | AD10: 37 | AE10: 42 | AF10: =ROUND(AVERAGE(U10:AE10),0) -> 48 | AG10: =VLOOKUP(A10,$AI$2:$AL$21,4,FALSE)+AF10 -> 52 | AI10: 700000178 | AJ10: Sector DESTELLO Karina | AK10: =_xlfn.XLOOKUP(AI10,'Histórico Actividad'!B:B,'Histórico Actividad'!P:P) -> 0.98698995 | AL10: =VLOOKUP(AK10,$AN$1:$AP$5,3,TRUE) -> 4
A11: 700000178 | B11: Sector DESTELLO Karina | C11: Sucre_Sincelejo | D11: 94 | E11: 99 | F11: 89 | G11: 106 | H11: 88 | I11: 70 | J11: 68 | K11: 94 | L11: 62 | M11: 119 | N11: 68 | O11: 95 | P11: 60 | Q11: =VLOOKUP(A11,[3]CUBO!$C:$DY,127,FALSE) -> 72 | R11: =VLOOKUP(A11,[4]CUBO!$C:$DY,127,FALSE) -> 98 | S11: =VLOOKUP(A11,[5]CUBO!$C:$DY,127,FALSE) -> 70 | T11: =VLOOKUP(A11,[6]CUBO!$C:$DY,127,FALSE) -> 65 | U11: =VLOOKUP(A11,[7]CUBO!$C:$DY,127,FALSE) -> 81 | V11: =VLOOKUP(A11,[8]CUBO!$C:$DY,127,FALSE) -> 103 | W11: =VLOOKUP(A11,[9]CUBO!$C:$DY,127,FALSE) -> 61 | X11: =VLOOKUP(A11,[10]CUBO!$C:$DY,127,FALSE) -> 81 | Y11: =VLOOKUP(A11,[11]CUBO!$C:$DY,127,FALSE) -> 108 | Z11: =VLOOKUP(A11,[12]CUBO!$C:$DY,127,FALSE) -> 81 | AA11: =_xlfn.XLOOKUP(A11,[13]CUBO!$B:$B,[13]CUBO!$DX:$DX) -> 72 | AB11: 74 | AC11: 73 | AD11: 76 | AE11: 112 | AF11: =ROUND(AVERAGE(U11:AE11),0) -> 84 | AG11: =VLOOKUP(A11,$AI$2:$AL$21,4,FALSE)+AF11 -> 88 | AI11: 700000232 | AJ11: Sector EXPRESIÓN Nayibe | AK11: =_xlfn.XLOOKUP(AI11,'Histórico Actividad'!B:B,'Histórico Actividad'!P:P) -> 0.9691358 | AL11: =VLOOKUP(AK11,$AN$1:$AP$5,3,TRUE) -> 4
A12: 700000423 | B12: Sector ARMONÍA Claudia | C12: Sucre_Sincelejo | D12: 69 | E12: 79 | F12: 68 | G12: 83 | H12: 86 | I12: 79 | J12: 73 | K12: 78 | L12: 89 | M12: 115 | N12: 80 | O12: 94 | P12: 66 | Q12: =VLOOKUP(A12,[3]CUBO!$C:$DY,127,FALSE) -> 81 | R12: =VLOOKUP(A12,[4]CUBO!$C:$DY,127,FALSE) -> 90 | S12: =VLOOKUP(A12,[5]CUBO!$C:$DY,127,FALSE) -> 75 | T12: =VLOOKUP(A12,[6]CUBO!$C:$DY,127,FALSE) -> 70 | U12: =VLOOKUP(A12,[7]CUBO!$C:$DY,127,FALSE) -> 67 | V12: =VLOOKUP(A12,[8]CUBO!$C:$DY,127,FALSE) -> 81 | W12: =VLOOKUP(A12,[9]CUBO!$C:$DY,127,FALSE) -> 71 | X12: =VLOOKUP(A12,[10]CUBO!$C:$DY,127,FALSE) -> 93 | Y12: =VLOOKUP(A12,[11]CUBO!$C:$DY,127,FALSE) -> 95 | Z12: =VLOOKUP(A12,[12]CUBO!$C:$DY,127,FALSE) -> 82 | AA12: =_xlfn.XLOOKUP(A12,[13]CUBO!$B:$B,[13]CUBO!$DX:$DX) -> 86 | AB12: 68 | AC12: 73 | AD12: 62 | AE12: 67 | AF12: =ROUND(AVERAGE(U12:AE12),0) -> 77 | AG12: =VLOOKUP(A12,$AI$2:$AL$21,4,FALSE)+AF12 -> 80 | AI12: 700000456 | AJ12: Sector ACUARELA Yeimi | AK12: =_xlfn.XLOOKUP(AI12,'Histórico Actividad'!B:B,'Histórico Actividad'!P:P) -> 1.0253782 | AL12: =VLOOKUP(AK12,$AN$1:$AP$5,3,TRUE) -> 3
A13: 700000232 | B13: Sector EXPRESIÓN Nayibe | C13: Poblaciones Cundinamarca_Facatativá/Madrid | D13: 37 | E13: 45 | F13: 52 | G13: 76 | H13: 45 | I13: 47 | J13: 69 | K13: 59 | L13: 50 | M13: 75 | N13: 95 | O13: 58 | P13: 57 | Q13: =VLOOKUP(A13,[3]CUBO!$C:$DY,127,FALSE) -> 64 | R13: =VLOOKUP(A13,[4]CUBO!$C:$DY,127,FALSE) -> 46 | S13: =VLOOKUP(A13,[5]CUBO!$C:$DY,127,FALSE) -> 29 | T13: =VLOOKUP(A13,[6]CUBO!$C:$DY,127,FALSE) -> 29 | U13: =VLOOKUP(A13,[7]CUBO!$C:$DY,127,FALSE) -> 31 | V13: =VLOOKUP(A13,[8]CUBO!$C:$DY,127,FALSE) -> 47 | W13: =VLOOKUP(A13,[9]CUBO!$C:$DY,127,FALSE) -> 46 | X13: =VLOOKUP(A13,[10]CUBO!$C:$DY,127,FALSE) -> 56 | Y13: =VLOOKUP(A13,[11]CUBO!$C:$DY,127,FALSE) -> 57 | Z13: =VLOOKUP(A13,[12]CUBO!$C:$DY,127,FALSE) -> 45 | AA13: =_xlfn.XLOOKUP(A13,[13]CUBO!$B:$B,[13]CUBO!$DX:$DX) -> 48 | AB13: 33 | AC13: 38 | AD13: 44 | AE13: 40 | AF13: =ROUND(AVERAGE(U13:AE13),0) -> 44 | AG13: =VLOOKUP(A13,$AI$2:$AL$21,4,FALSE)+AF13 -> 48 | AI13: 700000133 | AJ13: Sector INSPIRACIÓN Vanesa | AK13: =_xlfn.XLOOKUP(AI13,'Histórico Actividad'!B:B,'Histórico Actividad'!P:P) -> 1.009311 | AL13: =VLOOKUP(AK13,$AN$1:$AP$5,3,TRUE) -> 3
A14: 700000459 | B14: Sector MATICES Clery | C14: Poblaciones Cundinamarca_Facatativá/Madrid | D14: 26 | E14: 30 | F14: 52 | G14: 57 | H14: 37 | I14: 43 | J14: 46 | K14: 30 | L14: 31 | M14: 57 | N14: 55 | O14: 64 | P14: 46 | Q14: =VLOOKUP(A14,[3]CUBO!$C:$DY,127,FALSE) -> 48 | R14: =VLOOKUP(A14,[4]CUBO!$C:$DY,127,FALSE) -> 53 | S14: =VLOOKUP(A14,[5]CUBO!$C:$DY,127,FALSE) -> 37 | T14: =VLOOKUP(A14,[6]CUBO!$C:$DY,127,FALSE) -> 19 | U14: =VLOOKUP(A14,[7]CUBO!$C:$DY,127,FALSE) -> 31 | V14: =VLOOKUP(A14,[8]CUBO!$C:$DY,127,FALSE) -> 39 | W14: =VLOOKUP(A14,[9]CUBO!$C:$DY,127,FALSE) -> 46 | X14: =VLOOKUP(A14,[10]CUBO!$C:$DY,127,FALSE) -> 72 | Y14: =VLOOKUP(A14,[11]CUBO!$C:$DY,127,FALSE) -> 63 | Z14: =VLOOKUP(A14,[12]CUBO!$C:$DY,127,FALSE) -> 74 | AA14: =_xlfn.XLOOKUP(A14,[13]CUBO!$B:$B,[13]CUBO!$DX:$DX) -> 67 | AB14: 47 | AC14: 54 | AD14: 80 | AE14: 62 | AF14: =ROUND(AVERAGE(U14:AE14),0) -> 58 | AG14: =VLOOKUP(A14,$AI$2:$AL$21,4,FALSE)+AF14 -> 58 | AI14: 700000458 | AJ14: Sector LIENZO Ángela | AK14: =_xlfn.XLOOKUP(AI14,'Histórico Actividad'!B:B,'Histórico Actividad'!P:P) -> 1.0176803 | AL14: =VLOOKUP(AK14,$AN$1:$AP$5,3,TRUE) -> 3
A15: 700000245 | B15: Sector ARTESANÍA Fernanda | C15: Boyacá_Chiquinquirá Boyacá | D15: 24 | E15: 31 | F15: 50 | G15: 36 | H15: 31 | I15: 29 | J15: 42 | K15: 42 | L15: 28 | M15: 77 | N15: 36 | O15: 45 | P15: 36 | Q15: =VLOOKUP(A15,[3]CUBO!$C:$DY,127,FALSE) -> 43 | R15: =VLOOKUP(A15,[4]CUBO!$C:$DY,127,FALSE) -> 53 | S15: =VLOOKUP(A15,[5]CUBO!$C:$DY,127,FALSE) -> 46 | T15: =VLOOKUP(A15,[6]CUBO!$C:$DY,127,FALSE) -> 20 | U15: =VLOOKUP(A15,[7]CUBO!$C:$DY,127,FALSE) -> 43 | V15: =VLOOKUP(A15,[8]CUBO!$C:$DY,127,FALSE) -> 40 | W15: =VLOOKUP(A15,[9]CUBO!$C:$DY,127,FALSE) -> 44 | X15: =VLOOKUP(A15,[10]CUBO!$C:$DY,127,FALSE) -> 34 | Y15: =VLOOKUP(A15,[11]CUBO!$C:$DY,127,FALSE) -> 50 | Z15: =VLOOKUP(A15,[12]CUBO!$C:$DY,127,FALSE) -> 44 | AA15: =_xlfn.XLOOKUP(A15,[13]CUBO!$B:$B,[13]CUBO!$DX:$DX) -> 52 | AB15: 46 | AC15: 25 | AD15: 36 | AE15: 39 | AF15: =ROUND(AVERAGE(U15:AE15),0) -> 41 | AG15: =VLOOKUP(A15,$AI$2:$AL$21,4,FALSE)+AF15 -> 45 | AI15: 700000245 | AJ15: Sector ARTESANÍA Fernanda | AK15: =_xlfn.XLOOKUP(AI15,'Histórico Actividad'!B:B,'Histórico Actividad'!P:P) -> 0.95555556 | AL15: =VLOOKUP(AK15,$AN$1:$AP$5,3,TRUE) -> 4
A16: 700000466 | B16: Sector EMOCIONES Dolly | C16: Boyacá_DuitamaBoyacá | D16: 32 | E16: 26 | F16: 42 | G16: 35 | H16: 40 | I16: 44 | J16: 45 | K16: 23 | L16: 44 | M16: 68 | N16: 44 | O16: 38 | P16: 49 | Q16: =VLOOKUP(A16,[3]CUBO!$C:$DY,127,FALSE) -> 50 | R16: =VLOOKUP(A16,[4]CUBO!$C:$DY,127,FALSE) -> 40 | S16: =VLOOKUP(A16,[5]CUBO!$C:$DY,127,FALSE) -> 42 | T16: =VLOOKUP(A16,[6]CUBO!$C:$DY,127,FALSE) -> 20 | U16: =VLOOKUP(A16,[7]CUBO!$C:$DY,127,FALSE) -> 15 | V16: =VLOOKUP(A16,[8]CUBO!$C:$DY,127,FALSE) -> 46 | W16: =VLOOKUP(A16,[9]CUBO!$C:$DY,127,FALSE) -> 43 | X16: =VLOOKUP(A16,[10]CUBO!$C:$DY,127,FALSE) -> 42 | Y16: =VLOOKUP(A16,[11]CUBO!$C:$DY,127,FALSE) -> 50 | Z16: =VLOOKUP(A16,[12]CUBO!$C:$DY,127,FALSE) -> 60 | AA16: =_xlfn.XLOOKUP(A16,[13]CUBO!$B:$B,[13]CUBO!$DX:$DX) -> 45 | AB16: 36 | AC16: 39 | AD16: 53 | AE16: 46 | AF16: =ROUND(AVERAGE(U16:AE16),0) -> 43 | AG16: =VLOOKUP(A16,$AI$2:$AL$21,4,FALSE)+AF16 -> 46 | AI16: 700000022 | AJ16: Sector BRILLO Kelly | AK16: =_xlfn.XLOOKUP(AI16,'Histórico Actividad'!B:B,'Histórico Actividad'!P:P) -> 0.96411355 | AL16: =VLOOKUP(AK16,$AN$1:$AP$5,3,TRUE) -> 4
